Workbook

Sheet Consolidated KPI
A1: Game | B1: =DATE(2026,1,4) -> 46026 | C1: =B1+7 -> 46033 | D1: =C1+7 -> 46040 | E1: =D1+7 -> 46047 | F1: =E1+7 -> 46054 | G1: =F1+7 -> 46061 | H1: =G1+7 -> 46068 | I1: =H1+7 -> 46075 | J1: =I1+7 -> 46082 | ... BA1: =AZ1+7 -> 46383
A2: Taival - Wishlists | B2: ='KPI by Quarter'!B3 -> 4 | C2: ='KPI by Quarter'!C3 -> 2 | D2: ='KPI by Quarter'!D3 -> 16 | E2: ='KPI by Quarter'!E3 -> 0 | F2: ='KPI by Quarter'!F3 -> -2 | G2: ='KPI by Quarter'!G3 -> -6 | H2: ='KPI by Quarter'!H3 -> 4 | I2: ='KPI by Quarter'!I3 -> 26 | ... N2: ='KPI by Quarter'!N3 -> 27 | O2: ='KPI by Quarter'!B20 -> 249 | P2: ='KPI by Quarter'!C20 -> 363 | Q2: ='KPI by Quarter'!D20 -> 668 | R2: ='KPI by Quarter'!E20 -> 3186 | S2: ='KPI by Quarter'!F20 -> 827 | T2: ='KPI by Quarter'!G20 -> 0 | U2: ='KPI by Quarter'!H20 -> 0 | V2: ='KPI by Quarter'!I20 -> 0 | ... AA2: ='KPI by Quarter'!N20 -> 0 | AB2: ='KPI by Quarter'!B37 -> 0 | AC2: ='KPI by Quarter'!C37 -> 0 | AD2: ='KPI by Quarter'!D37 -> 0 | AE2: ='KPI by Quarter'!E37 -> 0 | AF2: ='KPI by Quarter'!F37 -> 0 | AG2: ='KPI by Quarter'!G37 -> 0 | AH2: ='KPI by Quarter'!H37 -> 0 | AI2: ='KPI by Quarter'!I37 -> 0 | ... AN2: ='KPI by Quarter'!N37 -> 0 | AO2: ='KPI by Quarter'!B54 -> 0 | AP2: ='KPI by Quarter'!C54 -> 0 | AQ2: ='KPI by Quarter'!D54 -> 0 | AR2: ='KPI by Quarter'!E54 -> 0 | AS2: ='KPI by Quarter'!F54 -> 0 | AT2: ='KPI by Quarter'!G54 -> 0 | AU2: ='KPI by Quarter'!H54 -> 0 | AV2: ='KPI by Quarter'!I54 -> 0 | ... BA2: ='KPI by Quarter'!N54 -> 0
A3: Taival - Impressions | B3: ='KPI by Quarter'!B4 -> 5095 | C3: ='KPI by Quarter'!C4 -> 6399 | D3: ='KPI by Quarter'!D4 -> 5490 | E3: ='KPI by Quarter'!E4 -> 5392 | F3: ='KPI by Quarter'!F4 -> 5225 | G3: ='KPI by Quarter'!G4 -> 4806 | H3: ='KPI by Quarter'!H4 -> 4560 | I3: ='KPI by Quarter'!I4 -> 4282 | ... N3: ='KPI by Quarter'!N4 -> 3196 | O3: ='KPI by Quarter'!B21 -> 3697 | P3: ='KPI by Quarter'!C21 -> 4970 | Q3: ='KPI by Quarter'!D21 -> 14388 | R3: ='KPI by Quarter'!E21 -> 16730 | S3: ='KPI by Quarter'!F21 -> 14879 | T3: ='KPI by Quarter'!G21 -> 0 | U3: ='KPI by Quarter'!H21 -> 0 | V3: ='KPI by Quarter'!I21 -> 0 | ... AA3: ='KPI by Quarter'!N21 -> 0 | AB3: 0 | AC3: 0 | AD3: 0 | AE3: 0 | AF3: 0 | AG3: 0 | AH3: 0 | AI3: 0 | AJ3: 0 | AK3: 0 | AL3: 0 | AM3: 0 | AN3: 0 | AO3: 0 | AP3: 0 | AQ3: 0 | AR3: 0 | AS3: 0 | AT3: 0 | AU3: 0 | AV3: 0 | AW3: 0 | AX3: 0 | AY3: 0 | AZ3: 0 | BA3: 0
A4: Taival - Visits | B4: ='KPI by Quarter'!B5 -> 1107 | C4: ='KPI by Quarter'!C5 -> 2049 | D4: ='KPI by Quarter'!D5 -> 1631 | E4: ='KPI by Quarter'!E5 -> 889 | F4: ='KPI by Quarter'!F5 -> 726 | G4: ='KPI by Quarter'!G5 -> 705 | H4: ='KPI by Quarter'!H5 -> 769 | I4: ='KPI by Quarter'!I5 -> 704 | ... N4: ='KPI by Quarter'!N5 -> 595 | O4: ='KPI by Quarter'!B22 -> 1276 | P4: ='KPI by Quarter'!C22 -> 2020 | Q4: ='KPI by Quarter'!D22 -> 2147 | R4: ='KPI by Quarter'!E22 -> 14587 | S4: ='KPI by Quarter'!F22 -> 6087 | T4: ='KPI by Quarter'!G22 -> 0 | U4: ='KPI by Quarter'!H22 -> 0 | V4: ='KPI by Quarter'!I22 -> 0 | ... AA4: ='KPI by Quarter'!N22 -> 0 | AB4: 0 | AC4: 0 | AD4: 0 | AE4: 0 | AF4: 0 | AG4: 0 | AH4: 0 | AI4: 0 | AJ4: 0 | AK4: 0 | AL4: 0 | AM4: 0 | AN4: 0 | AO4: 0 | AP4: 0 | AQ4: 0 | AR4: 0 | AS4: 0 | AT4: 0 | AU4: 0 | AV4: 0 | AW4: 0 | AX4: 0 | AY4: 0 | AZ4: 0 | BA4: 0
A6: Colossus - Wishlists | B6: ='KPI by Quarter'!B7 -> 22 | C6: ='KPI by Quarter'!C7 -> 22 | D6: ='KPI by Quarter'!D7 -> 23 | E6: ='KPI by Quarter'!E7 -> 20 | F6: ='KPI by Quarter'!F7 -> 286 | G6: ='KPI by Quarter'!G7 -> 90 | H6: ='KPI by Quarter'!H7 -> 132 | I6: ='KPI by Quarter'!I7 -> 54 | ... N6: ='KPI by Quarter'!N7 -> 106 | O6: ='KPI by Quarter'!B24 -> 83 | P6: ='KPI by Quarter'!C24 -> 92 | Q6: ='KPI by Quarter'!D24 -> 295 | R6: ='KPI by Quarter'!E24 -> 514 | S6: ='KPI by Quarter'!F24 -> 272 | T6: ='KPI by Quarter'!G24 -> 0 | U6: ='KPI by Quarter'!H24 -> 0 | V6: ='KPI by Quarter'!I24 -> 0 | ... AA6: ='KPI by Quarter'!N24 -> 0 | AB6: ='KPI by Quarter'!B41 -> 0 | AC6: ='KPI by Quarter'!C41 -> 0 | AD6: ='KPI by Quarter'!D41 -> 0 | AE6: ='KPI by Quarter'!E41 -> 0 | AF6: ='KPI by Quarter'!F41 -> 0 | AG6: ='KPI by Quarter'!G41 -> 0 | AH6: ='KPI by Quarter'!H41 -> 0 | AI6: ='KPI by Quarter'!I41 -> 0 | ... AN6: ='KPI by Quarter'!N41 -> 0 | AO6: ='KPI by Quarter'!B58 -> 0 | AP6: ='KPI by Quarter'!C58 -> 0 | AQ6: ='KPI by Quarter'!D58 -> 0 | AR6: ='KPI by Quarter'!E58 -> 0 | AS6: ='KPI by Quarter'!F58 -> 0 | AT6: ='KPI by Quarter'!G58 -> 0 | AU6: ='KPI by Quarter'!H58 -> 0 | AV6: ='KPI by Quarter'!I58 -> 0 | ... BA6: ='KPI by Quarter'!N58 -> 0
A7: Colossus - Impressions | B7: ='KPI by Quarter'!B8 -> 1568 | C7: ='KPI by Quarter'!C8 -> 1879 | D7: ='KPI by Quarter'!D8 -> 2210 | E7: ='KPI by Quarter'!E8 -> 2066 | F7: ='KPI by Quarter'!F8 -> 3259 | G7: ='KPI by Quarter'!G8 -> 2320 | H7: ='KPI by Quarter'!H8 -> 2324 | I7: ='KPI by Quarter'!I8 -> 2304 | ... N7: ='KPI by Quarter'!N8 -> 5374 | O7: ='KPI by Quarter'!B25 -> 3631 | P7: ='KPI by Quarter'!C25 -> 3253 | Q7: ='KPI by Quarter'!D25 -> 14258 | R7: ='KPI by Quarter'!E25 -> 6946 | S7: ='KPI by Quarter'!F25 -> 7164 | T7: ='KPI by Quarter'!G25 -> 0 | U7: ='KPI by Quarter'!H25 -> 0 | V7: ='KPI by Quarter'!I25 -> 0 | ... AA7: ='KPI by Quarter'!N25 -> 0 | AB7: 0 | AC7: 0 | AD7: 0 | AE7: 0 | AF7: 0 | AG7: 0 | AH7: 0 | AI7: 0 | AJ7: 0 | AK7: 0 | AL7: 0 | AM7: 0 | AN7: 0 | AO7: 0 | AP7: 0 | AQ7: 0 | AR7: 0 | AS7: 0 | AT7: 0 | AU7: 0 | AV7: 0 | AW7: 0 | AX7: 0 | AY7: 0 | AZ7: 0 | BA7: 0
A8: Colossus - Visits | B8: ='KPI by Quarter'!B9 -> 424 | C8: ='KPI by Quarter'!C9 -> 682 | D8: ='KPI by Quarter'!D9 -> 591 | E8: ='KPI by Quarter'!E9 -> 765 | F8: ='KPI by Quarter'!F9 -> 1007 | G8: ='KPI by Quarter'!G9 -> 798 | H8: ='KPI by Quarter'!H9 -> 912 | I8: ='KPI by Quarter'!I9 -> 832 | ... N8: ='KPI by Quarter'!N9 -> 1046 | O8: ='KPI by Quarter'!B26 -> 887 | P8: ='KPI by Quarter'!C26 -> 839 | Q8: ='KPI by Quarter'!D26 -> 1232 | R8: ='KPI by Quarter'!E26 -> 1542 | S8: ='KPI by Quarter'!F26 -> 1502 | T8: ='KPI by Quarter'!G26 -> 0 | U8: ='KPI by Quarter'!H26 -> 0 | V8: ='KPI by Quarter'!I26 -> 0 | ... AA8: ='KPI by Quarter'!N26 -> 0 | AB8: 0 | AC8: 0 | AD8: 0 | AE8: 0 | AF8: 0 | AG8: 0 | AH8: 0 | AI8: 0 | AJ8: 0 | AK8: 0 | AL8: 0 | AM8: 0 | AN8: 0 | AO8: 0 | AP8: 0 | AQ8: 0 | AR8: 0 | AS8: 0 | AT8: 0 | AU8: 0 | AV8: 0 | AW8: 0 | AX8: 0 | AY8: 0 | AZ8: 0 | BA8: 0
A10: Petunia's Purgatory - Wishlists | B10: ='KPI by Quarter'!B11 -> 155 | C10: ='KPI by Quarter'!C11 -> 36 | D10: ='KPI by Quarter'!D11 -> 16 | E10: ='KPI by Quarter'!E11 -> 12 | F10: ='KPI by Quarter'!F11 -> 23 | G10: ='KPI by Quarter'!G11 -> 30 | H10: ='KPI by Quarter'!H11 -> 29 | I10: ='KPI by Quarter'!I11 -> 76 | ... N10: ='KPI by Quarter'!N11 -> 17 | O10: ='KPI by Quarter'!B28 -> 41 | P10: ='KPI by Quarter'!C28 -> 35 | Q10: ='KPI by Quarter'!D28 -> 28 | R10: ='KPI by Quarter'!E28 -> 26 | S10: ='KPI by Quarter'!F28 -> 14 | T10: ='KPI by Quarter'!G28 -> 0 | U10: ='KPI by Quarter'!H28 -> 0 | V10: ='KPI by Quarter'!I28 -> 0 | ... AA10: ='KPI by Quarter'!N28 -> 0 | AB10: ='KPI by Quarter'!B45 -> 0 | AC10: ='KPI by Quarter'!C45 -> 0 | AD10: ='KPI by Quarter'!D45 -> 0 | AE10: ='KPI by Quarter'!E45 -> 0 | AF10: ='KPI by Quarter'!F45 -> 0 | AG10: ='KPI by Quarter'!G45 -> 0 | AH10: ='KPI by Quarter'!H45 -> 0 | AI10: ='KPI by Quarter'!I45 -> 0 | ... AN10: ='KPI by Quarter'!N45 -> 0 | AO10: ='KPI by Quarter'!B62 -> 0 | AP10: ='KPI by Quarter'!C62 -> 0 | AQ10: ='KPI by Quarter'!D62 -> 0 | AR10: ='KPI by Quarter'!E62 -> 0 | AS10: ='KPI by Quarter'!F62 -> 0 | AT10: ='KPI by Quarter'!G62 -> 0 | AU10: ='KPI by Quarter'!H62 -> 0 | AV10: ='KPI by Quarter'!I62 -> 0 | ... BA10: ='KPI by Quarter'!N62 -> 0
A11: Petunia's Purgatory - Impressions | B11: ='KPI by Quarter'!B12 -> 3279 | C11: ='KPI by Quarter'!C12 -> 4700 | D11: ='KPI by Quarter'!D12 -> 3386 | E11: ='KPI by Quarter'!E12 -> 2992 | F11: ='KPI by Quarter'!F12 -> 3010 | G11: ='KPI by Quarter'!G12 -> 3278 | H11: ='KPI by Quarter'!H12 -> 3624 | I11: ='KPI by Quarter'!I12 -> 3748 | ... N11: ='KPI by Quarter'!N12 -> 3455 | O11: ='KPI by Quarter'!B29 -> 3364 | P11: ='KPI by Quarter'!C29 -> 3463 | Q11: ='KPI by Quarter'!D29 -> 2997 | R11: ='KPI by Quarter'!E29 -> 2844 | S11: ='KPI by Quarter'!F29 -> 2837 | T11: ='KPI by Quarter'!G29 -> 0 | U11: ='KPI by Quarter'!H29 -> 0 | V11: ='KPI by Quarter'!I29 -> 0 | ... AA11: ='KPI by Quarter'!N29 -> 0 | AB11: 0 | AC11: 0 | AD11: 0 | AE11: 0 | AF11: 0 | AG11: 0 | AH11: 0 | AI11: 0 | AJ11: 0 | AK11: 0 | AL11: 0 | AM11: 0 | AN11: 0 | AO11: 0 | AP11: 0 | AQ11: 0 | AR11: 0 | AS11: 0 | AT11: 0 | AU11: 0 | AV11: 0 | AW11: 0 | AX11: 0 | AY11: 0 | AZ11: 0 | BA11: 0
A12: Petunia's Purgatory - Visits | B12: ='KPI by Quarter'!B13 -> 1513 | C12: ='KPI by Quarter'!C13 -> 833 | D12: ='KPI by Quarter'!D13 -> 795 | E12: ='KPI by Quarter'!E13 -> 690 | F12: ='KPI by Quarter'!F13 -> 1056 | G12: ='KPI by Quarter'!G13 -> 885 | H12: ='KPI by Quarter'!H13 -> 1126 | I12: ='KPI by Quarter'!I13 -> 906 | ... N12: ='KPI by Quarter'!N13 -> 4897 | O12: ='KPI by Quarter'!B30 -> 5782 | P12: ='KPI by Quarter'!C30 -> 7678 | Q12: ='KPI by Quarter'!D30 -> 5615 | R12: ='KPI by Quarter'!E30 -> 5242 | S12: ='KPI by Quarter'!F30 -> 7094 | T12: ='KPI by Quarter'!G30 -> 0 | U12: ='KPI by Quarter'!H30 -> 0 | V12: ='KPI by Quarter'!I30 -> 0 | ... AA12: ='KPI by Quarter'!N30 -> 0 | AB12: 0 | AC12: 0 | AD12: 0 | AE12: 0 | AF12: 0 | AG12: 0 | AH12: 0 | AI12: 0 | AJ12: 0 | AK12: 0 | AL12: 0 | AM12: 0 | AN12: 0 | AO12: 0 | AP12: 0 | AQ12: 0 | AR12: 0 | AS12: 0 | AT12: 0 | AU12: 0 | AV12: 0 | AW12: 0 | AX12: 0 | AY12: 0 | AZ12: 0 | BA12: 0
A14: Fleet Breakers - Wishlists | B14: ='KPI by Quarter'!B15 -> 49 | C14: ='KPI by Quarter'!C15 -> 76 | D14: ='KPI by Quarter'!D15 -> 138 | E14: ='KPI by Quarter'!E15 -> 33 | F14: ='KPI by Quarter'!F15 -> -2 | G14: ='KPI by Quarter'!G15 -> 12 | H14: ='KPI by Quarter'!H15 -> 1 | I14: ='KPI by Quarter'!I15 -> 0 | ... N14: ='KPI by Quarter'!N15 -> -2 | O14: ='KPI by Quarter'!B32 -> 8 | P14: ='KPI by Quarter'!C32 -> 8 | Q14: ='KPI by Quarter'!D32 -> -4 | R14: ='KPI by Quarter'!E32 -> -2 | S14: ='KPI by Quarter'!F32 -> 15 | T14: ='KPI by Quarter'!G32 -> 0 | U14: ='KPI by Quarter'!H32 -> 0 | V14: ='KPI by Quarter'!I32 -> 0 | ... AA14: ='KPI by Quarter'!N32 -> 0 | AB14: ='KPI by Quarter'!B49 -> 0 | AC14: ='KPI by Quarter'!C49 -> 0 | AD14: ='KPI by Quarter'!D49 -> 0 | AE14: ='KPI by Quarter'!E49 -> 0 | AF14: ='KPI by Quarter'!F49 -> 0 | AG14: ='KPI by Quarter'!G49 -> 0 | AH14: ='KPI by Quarter'!H49 -> 0 | AI14: ='KPI by Quarter'!I49 -> 0 | ... AN14: ='KPI by Quarter'!N49 -> 0 | AO14: ='KPI by Quarter'!B66 -> 0 | AP14: ='KPI by Quarter'!C66 -> 0 | AQ14: ='KPI by Quarter'!D66 -> 0 | AR14: ='KPI by Quarter'!E66 -> 0 | AS14: ='KPI by Quarter'!F66 -> 0 | AT14: ='KPI by Quarter'!G66 -> 0 | AU14: ='KPI by Quarter'!H66 -> 0 | AV14: ='KPI by Quarter'!I66 -> 0 | ... BA14: ='KPI by Quarter'!N66 -> 0
A15: Fleet Breakers - Impressions | B15: ='KPI by Quarter'!B16 -> 5095 | C15: ='KPI by Quarter'!C16 -> 6399 | D15: ='KPI by Quarter'!D16 -> 5490 | E15: ='KPI by Quarter'!E16 -> 5392 | F15: ='KPI by Quarter'!F16 -> 5225 | G15: ='KPI by Quarter'!G16 -> 4806 | H15: ='KPI by Quarter'!H16 -> 4560 | I15: ='KPI by Quarter'!I16 -> 4282 | J15: 4123 | K15: ='KPI by Quarter'!K16 -> 4376 | L15: ='KPI by Quarter'!L16 -> 3950 | M15: ='KPI by Quarter'!M16 -> 5167 | N15: ='KPI by Quarter'!N16 -> 4403 | O15: ='KPI by Quarter'!B33 -> 3652 | P15: ='KPI by Quarter'!C33 -> 3825 | Q15: ='KPI by Quarter'!D33 -> 5291 | R15: ='KPI by Quarter'!E33 -> 4857 | S15: ='KPI by Quarter'!F33 -> 6270 | T15: ='KPI by Quarter'!G33 -> 0 | U15: ='KPI by Quarter'!H33 -> 0 | V15: ='KPI by Quarter'!I33 -> 0 | ... AA15: ='KPI by Quarter'!N33 -> 0 | AB15: 0 | AC15: 0 | AD15: 0 | AE15: 0 | AF15: 0 | AG15: 0 | AH15: 0 | AI15: 0 | AJ15: 0 | AK15: 0 | AL15: 0 | AM15: 0 | AN15: 0 | AO15: 0 | AP15: 0 | AQ15: 0 | AR15: 0 | AS15: 0 | AT15: 0 | AU15: 0 | AV15: 0 | AW15: 0 | AX15: 0 | AY15: 0 | AZ15: 0 | BA15: 0
A16: Fleet Breakers - Visits | B16: ='KPI by Quarter'!B17 -> 1107 | C16: ='KPI by Quarter'!C17 -> 2049 | D16: ='KPI by Quarter'!D17 -> 1631 | E16: ='KPI by Quarter'!E17 -> 889 | F16: ='KPI by Quarter'!F17 -> 726 | G16: ='KPI by Quarter'!G17 -> 705 | H16: ='KPI by Quarter'!H17 -> 769 | I16: ='KPI by Quarter'!I17 -> 704 | ... N16: ='KPI by Quarter'!N17 -> 707 | O16: ='KPI by Quarter'!B34 -> 783 | P16: ='KPI by Quarter'!C34 -> 790 | Q16: ='KPI by Quarter'!D34 -> 614 | R16: ='KPI by Quarter'!E34 -> 891 | S16: ='KPI by Quarter'!F34 -> 1106 | T16: ='KPI by Quarter'!G34 -> 0 | U16: ='KPI by Quarter'!H34 -> 0 | V16: ='KPI by Quarter'!I34 -> 0 | ... AA16: ='KPI by Quarter'!N34 -> 0 | AB16: 0 | AC16: 0 | AD16: 0 | AE16: 0 | AF16: 0 | AG16: 0 | AH16: 0 | AI16: 0 | AJ16: 0 | AK16: 0 | AL16: 0 | AM16: 0 | AN16: 0 | AO16: 0 | AP16: 0 | AQ16: 0 | AR16: 0 | AS16: 0 | AT16: 0 | AU16: 0 | AV16: 0 | AW16: 0 | AX16: 0 | AY16: 0 | AZ16: 0 | BA16: 0
A18: Latest WoW% | B18: Taival | C18: Colossus | D18: Putania's Purgatory | E18: Fleet Breakers | G18: Add Data on other sheets for this sheet to update.
A19: Wishlists | B19: {=IFERROR(_xlfn.LET(_xlpm.vals,_xlfn._xlws.FILTER(B2:BA2,(B2:BA2<>0)*(ISNUMBER(B2:BA2))),_xlpm.lastVal,INDEX(_xlpm.vals,COLUMNS(_xlpm.vals)),_xlpm.prevVal,INDEX(_xlpm.vals,COLUMNS(_xlpm.vals)-1),(_xlpm.lastVal-_xlpm.prevVal)/ABS(_xlpm.prevVal)),"-")} -> -0.74042687 | C19: {=IFERROR(_xlfn.LET(_xlpm.vals,_xlfn._xlws.FILTER(B6:BA6,(B6:BA6<>0)*(ISNUMBER(B6:BA6))),_xlpm.lastVal,INDEX(_xlpm.vals,COLUMNS(_xlpm.vals)),_xlpm.prevVal,INDEX(_xlpm.vals,COLUMNS(_xlpm.vals)-1),(_xlpm.lastVal-_xlpm.prevVal)/ABS(_xlpm.prevVal)),"-")} -> -0.47081712 | D19: {=IFERROR(_xlfn.LET(_xlpm.vals,_xlfn._xlws.FILTER(B10:BA10,(B10:BA10<>0)*(ISNUMBER(B10:BA10))),_xlpm.lastVal,INDEX(_xlpm.vals,COLUMNS(_xlpm.vals)),_xlpm.prevVal,INDEX(_xlpm.vals,COLUMNS(_xlpm.vals)-1),(_xlpm.lastVal-_xlpm.prevVal)/ABS(_xlpm.prevVal)),"-")} -> -0.46153846 | E19: {=IFERROR(_xlfn.LET(_xlpm.vals,_xlfn._xlws.FILTER(B14:BA14,(B14:BA14<>0)*(ISNUMBER(B14:BA14))),_xlpm.lastVal,INDEX(_xlpm.vals,COLUMNS(_xlpm.vals)),_xlpm.prevVal,INDEX(_xlpm.vals,COLUMNS(_xlpm.vals)-1),(_xlpm.lastVal-_xlpm.prevVal)/ABS(_xlpm.prevVal)),"-")} -> 8.5
A20: Impressions | B20: {=IFERROR(_xlfn.LET(_xlpm.vals,_xlfn._xlws.FILTER(B3:BA3,(B3:BA3<>0)*(ISNUMBER(B3:BA3))),_xlpm.lastVal,INDEX(_xlpm.vals,COLUMNS(_xlpm.vals)),_xlpm.prevVal,INDEX(_xlpm.vals,COLUMNS(_xlpm.vals)-1),(_xlpm.lastVal-_xlpm.prevVal)/ABS(_xlpm.prevVal)),"-")} -> -0.11063957 | C20: {=IFERROR(_xlfn.LET(_xlpm.vals,_xlfn._xlws.FILTER(B7:BA7,(B7:BA7<>0)*(ISNUMBER(B7:BA7))),_xlpm.lastVal,INDEX(_xlpm.vals,COLUMNS(_xlpm.vals)),_xlpm.prevVal,INDEX(_xlpm.vals,COLUMNS(_xlpm.vals)-1),(_xlpm.lastVal-_xlpm.prevVal)/ABS(_xlpm.prevVal)),"-")} -> 0.03138497 | D20: {=IFERROR(_xlfn.LET(_xlpm.vals,_xlfn._xlws.FILTER(B11:BA11,(B11:BA11<>0)*(ISNUMBER(B11:BA11))),_xlpm.lastVal,INDEX(_xlpm.vals,COLUMNS(_xlpm.vals)),_xlpm.prevVal,INDEX(_xlpm.vals,COLUMNS(_xlpm.vals)-1),(_xlpm.lastVal-_xlpm.prevVal)/ABS(_xlpm.prevVal)),"-")} -> -0.0024613221 | E20: {=IFERROR(_xlfn.LET(_xlpm.vals,_xlfn._xlws.FILTER(B15:BA15,(B15:BA15<>0)*(ISNUMBER(B15:BA15))),_xlpm.lastVal,INDEX(_xlpm.vals,COLUMNS(_xlpm.vals)),_xlpm.prevVal,INDEX(_xlpm.vals,COLUMNS(_xlpm.vals)-1),(_xlpm.lastVal-_xlpm.prevVal)/ABS(_xlpm.prevVal)),"-")} -> 0.29092032
A21: Visits | B21: {=IFERROR(_xlfn.LET(_xlpm.vals,_xlfn._xlws.FILTER(B4:BA4,(B4:BA4<>0)*(ISNUMBER(B4:BA4))),_xlpm.lastVal,INDEX(_xlpm.vals,COLUMNS(_xlpm.vals)),_xlpm.prevVal,INDEX(_xlpm.vals,COLUMNS(_xlpm.vals)-1),(_xlpm.lastVal-_xlpm.prevVal)/ABS(_xlpm.prevVal)),"-")} -> -0.58271063 | C21: {=IFERROR(_xlfn.LET(_xlpm.vals,_xlfn._xlws.FILTER(B8:BA8,(B8:BA8<>0)*(ISNUMBER(B8:BA8))),_xlpm.lastVal,INDEX(_xlpm.vals,COLUMNS(_xlpm.vals)),_xlpm.prevVal,INDEX(_xlpm.vals,COLUMNS(_xlpm.vals)-1),(_xlpm.lastVal-_xlpm.prevVal)/ABS(_xlpm.prevVal)),"-")} -> -0.025940337 | D21: {=IFERROR(_xlfn.LET(_xlpm.vals,_xlfn._xlws.FILTER(B12:BA12,(B12:BA12<>0)*(ISNUMBER(B12:BA12))),_xlpm.lastVal,INDEX(_xlpm.vals,COLUMNS(_xlpm.vals)),_xlpm.prevVal,INDEX(_xlpm.vals,COLUMNS(_xlpm.vals)-1),(_xlpm.lastVal-_xlpm.prevVal)/ABS(_xlpm.prevVal)),"-")} -> 0.35330027 | E21: {=IFERROR(_xlfn.LET(_xlpm.vals,_xlfn._xlws.FILTER(B16:BA16,(B16:BA16<>0)*(ISNUMBER(B16:BA16))),_xlpm.lastVal,INDEX(_xlpm.vals,COLUMNS(_xlpm.vals)),_xlpm.prevVal,INDEX(_xlpm.vals,COLUMNS(_xlpm.vals)-1),(_xlpm.lastVal-_xlpm.prevVal)/ABS(_xlpm.prevVal)),"-")} -> 0.24130191
A23: Total Achieved | B23: Taival | C23: Colossus | D23: Putania's Purgatory | E23: Fleet Breakers
A24: Wishlists | B24: =SUM(B2:BA2) -> 5407 | C24: =SUM(B6:BA6) -> 2482 | D24: =SUM(B10:BA10) -> 1569 | E24: =SUM(B14:BA14) -> 317
A25: Impressions | B25: =SUMIF(B3:BA3,"<>-") -> 114812 | C25: =SUMIF(B7:BA7,"<>-") -> 73723 | D25: =SUMIF(B11:BA11,"<>-") -> 226258 | E25: =SUMIF(B15:BA15,"<>-") -> 87163
A26: Visits | B26: =SUMIF(B4:BA4,"<>-") -> 38003 | C26: =SUMIF(B8:BA8,"<>-") -> 17126 | D26: =SUMIF(B12:BA12,"<>-") -> 53029 | E26: =SUMIF(B16:BA16,"<>-") -> 16589
A28: Noor - Wishlists | B28: ='KPI by Quarter'!B71 | C28: ='KPI by Quarter'!C71 | D28: ='KPI by Quarter'!D71 | E28: ='KPI by Quarter'!E71 | F28: ='KPI by Quarter'!F71 | G28: ='KPI by Quarter'!G71 | H28: ='KPI by Quarter'!H71 | I28: ='KPI by Quarter'!I71 | ... N28: ='KPI by Quarter'!N71 | O28: ='KPI by Quarter'!B76 | P28: ='KPI by Quarter'!C76 | Q28: ='KPI by Quarter'!D76 | R28: ='KPI by Quarter'!E76
A29: Noor - Impressions | B29: ='KPI by Quarter'!B72 | C29: ='KPI by Quarter'!C72 | D29: ='KPI by Quarter'!D72 | E29: ='KPI by Quarter'!E72 | F29: ='KPI by Quarter'!F72 | G29: ='KPI by Quarter'!G72 | H29: ='KPI by Quarter'!H72 | I29: ='KPI by Quarter'!I72 | ... N29: ='KPI by Quarter'!N72 | O29: ='KPI by Quarter'!B77 | P29: ='KPI by Quarter'!C77 | Q29: ='KPI by Quarter'!D77 | R29: ='KPI by Quarter'!E77
A30: Noor - Visits | B30: ='KPI by Quarter'!B73 | C30: ='KPI by Quarter'!C73 | D30: ='KPI by Quarter'!D73 | E30: ='KPI by Quarter'!E73 | F30: ='KPI by Quarter'!F73 | G30: ='KPI by Quarter'!G73 | H30: ='KPI by Quarter'!H73 | I30: ='KPI by Quarter'!I73 | ... N30: ='KPI by Quarter'!N73 | O30: ='KPI by Quarter'!B78 | P30: ='KPI by Quarter'!C78 | Q30: ='KPI by Quarter'!D78 | R30: ='KPI by Quarter'!E78

Sheet KPI by Quarter
A1: Quarter 1 | P1: Quarter Totals
A2: Taival | B2: 1/4 | C2: 1/11 | D2: 1/18 | E2: 1/25 | F2: 2/1 | G2: 2/8 | H2: 2/15 | I2: 2/22 | J2: 3/1 | K2: 3/8 | L2: 3/15 | M2: 3/22 | N2: 3/29 | O2: WoW% | P2: Total
A3: Wishlists | B3: =SUMIF(Taival_WL!$A:$A,"<="&B2,Taival_WL!$H:$H) -> 4 | C3: =SUMIFS(Taival_WL!$H:$H,Taival_WL!$A:$A,">"&B2,Taival_WL!$A:$A,"<="&C2) -> 2 | D3: =SUMIFS(Taival_WL!$H:$H,Taival_WL!$A:$A,">"&C2,Taival_WL!$A:$A,"<="&D2) -> 16 | E3: =SUMIFS(Taival_WL!$H:$H,Taival_WL!$A:$A,">"&D2,Taival_WL!$A:$A,"<="&E2) -> 0 | F3: =SUMIFS(Taival_WL!$H:$H,Taival_WL!$A:$A,">"&E2,Taival_WL!$A:$A,"<="&F2) -> -2 | G3: =SUMIFS(Taival_WL!$H:$H,Taival_WL!$A:$A,">"&F2,Taival_WL!$A:$A,"<="&G2) -> -6 | H3: =SUMIFS(Taival_WL!$H:$H,Taival_WL!$A:$A,">"&G2,Taival_WL!$A:$A,"<="&H2) -> 4 | I3: =SUMIFS(Taival_WL!$H:$H,Taival_WL!$A:$A,">"&H2,Taival_WL!$A:$A,"<="&I2) -> 26 | J3: =SUMIFS(Taival_WL!$H:$H,Taival_WL!$A:$A,">"&I2,Taival_WL!$A:$A,"<="&J2) -> 3 | ... N3: =SUMIFS(Taival_WL!$H:$H,Taival_WL!$A:$A,">"&M2,Taival_WL!$A:$A,"<="&N2) -> 27 | O3: {=IFERROR(_xlfn.LET( _xlpm.rng,B3:N3, _xlpm.lastCol,MAX(IF(ISNUMBER(_xlpm.rng)*(_xlpm.rng<>0),COLUMN(_xlpm.rng),0)), _xlpm.secondLastCol,MAX(IF((ISNUMBER(_xlpm.rng)*(_xlpm.rng<>0)*(COLUMN(_xlpm.rng)<_xlpm.lastCol)),COLUMN(_xlpm.rng),0)), _xlpm.lastVal,INDEX(B3:N3,1,_xlpm.lastCol-1), _xlpm.secondLastVal,INDEX(B3:N3,1,_xlpm.secondLastCol-1), IF(OR(_xlpm.secondLastCol=0,_xlpm.lastCol=0),"-",(_xlpm.lastVal-_xlpm.secondLastVal)/ABS(_xlpm.secondLastVal)) ),"-")} -> 0.22727273 | P3: =SUM(B3:N3) -> 114
A4: Impressions | B4: 5095 | C4: 6399 | D4: 5490 | E4: 5392 | F4: 5225 | G4: 4806 | H4: 4560 | I4: 4282 | J4: 5673 | K4: 3043 | L4: 3184 | M4: 3803 | N4: 3196 | O4: {=IFERROR(_xlfn.LET( _xlpm.rng,B4:N4, _xlpm.lastCol,MAX(IF(ISNUMBER(_xlpm.rng)*(_xlpm.rng<>0),COLUMN(_xlpm.rng),0)), _xlpm.secondLastCol,MAX(IF((ISNUMBER(_xlpm.rng)*(_xlpm.rng<>0)*(COLUMN(_xlpm.rng)<_xlpm.lastCol)),COLUMN(_xlpm.rng),0)), _xlpm.lastVal,INDEX(B4:N4,1,_xlpm.lastCol-1), _xlpm.secondLastVal,INDEX(B4:N4,1,_xlpm.secondLastCol-1), IF(OR(_xlpm.secondLastCol=0,_xlpm.lastCol=0),"-",(_xlpm.lastVal-_xlpm.secondLastVal)/ABS(_xlpm.secondLastVal)) ),"-")} -> -0.15961083 | P4: =SUM(B4:N4) -> 60148
A5: Visits | B5: 1107 | C5: 2049 | D5: 1631 | E5: 889 | F5: 726 | G5: 705 | H5: 769 | I5: 704 | J5: 906 | K5: 680 | L5: 507 | M5: 618 | N5: 595 | O5: {=IFERROR(_xlfn.LET( _xlpm.rng,B5:N5, _xlpm.lastCol,MAX(IF(ISNUMBER(_xlpm.rng)*(_xlpm.rng<>0),COLUMN(_xlpm.rng),0)), _xlpm.secondLastCol,MAX(IF((ISNUMBER(_xlpm.rng)*(_xlpm.rng<>0)*(COLUMN(_xlpm.rng)<_xlpm.lastCol)),COLUMN(_xlpm.rng),0)), _xlpm.lastVal,INDEX(B5:N5,1,_xlpm.lastCol-1), _xlpm.secondLastVal,INDEX(B5:N5,1,_xlpm.secondLastCol-1), IF(OR(_xlpm.secondLastCol=0,_xlpm.lastCol=0),"-",(_xlpm.lastVal-_xlpm.secondLastVal)/ABS(_xlpm.secondLastVal)) ),"-")} -> -0.037216828 | P5: =SUM(B5:N5) -> 11886
A6: Colossus - Eternal Blight | B6: 1/4 | C6: 1/11 | D6: 1/18 | E6: 1/25 | F6: 2/1 | G6: 2/8 | H6: 2/15 | I6: 2/22 | J6: 3/1 | K6: 3/8 | L6: 3/15 | M6: 3/22 | N6: 3/29 | O6: WoW% | P6: Total
A7: Wishlists | B7: =SUMIF('Colossus - Eternal Blight_WL'!$A:$A,"<="&B6,'Colossus - Eternal Blight_WL'!$H:$H) -> 22 | C7: =SUMIFS('Colossus - Eternal Blight_WL'!$H:$H,'Colossus - Eternal Blight_WL'!$A:$A,">"&B6,'Colossus - Eternal Blight_WL'!$A:$A,"<="&C6) -> 22 | D7: =SUMIFS('Colossus - Eternal Blight_WL'!$H:$H,'Colossus - Eternal Blight_WL'!$A:$A,">"&C6,'Colossus - Eternal Blight_WL'!$A:$A,"<="&D6) -> 23 | E7: =SUMIFS('Colossus - Eternal Blight_WL'!$H:$H,'Colossus - Eternal Blight_WL'!$A:$A,">"&D6,'Colossus - Eternal Blight_WL'!$A:$A,"<="&E6) -> 20 | F7: =SUMIFS('Colossus - Eternal Blight_WL'!$H:$H,'Colossus - Eternal Blight_WL'!$A:$A,">"&E6,'Colossus - Eternal Blight_WL'!$A:$A,"<="&F6) -> 286 | G7: =SUMIFS('Colossus - Eternal Blight_WL'!$H:$H,'Colossus - Eternal Blight_WL'!$A:$A,">"&F6,'Colossus - Eternal Blight_WL'!$A:$A,"<="&G6) -> 90 | H7: =SUMIFS('Colossus - Eternal Blight_WL'!$H:$H,'Colossus - Eternal Blight_WL'!$A:$A,">"&G6,'Colossus - Eternal Blight_WL'!$A:$A,"<="&H6) -> 132 | I7: =SUMIFS('Colossus - Eternal Blight_WL'!$H:$H,'Colossus - Eternal Blight_WL'!$A:$A,">"&H6,'Colossus - Eternal Blight_WL'!$A:$A,"<="&I6) -> 54 | J7: =SUMIFS('Colossus - Eternal Blight_WL'!$H:$H,'Colossus - Eternal Blight_WL'!$A:$A,">"&I6,'Colossus - Eternal Blight_WL'!$A:$A,"<="&J6) -> 89 | ... N7: =SUMIFS('Colossus - Eternal Blight_WL'!$H:$H,'Colossus - Eternal Blight_WL'!$A:$A,">"&M6,'Colossus - Eternal Blight_WL'!$A:$A,"<="&N6) -> 106 | O7: {=IFERROR(_xlfn.LET( _xlpm.rng,B7:N7, _xlpm.lastCol,MAX(IF(ISNUMBER(_xlpm.rng)*(_xlpm.rng<>0),COLUMN(_xlpm.rng),0)), _xlpm.secondLastCol,MAX(IF((ISNUMBER(_xlpm.rng)*(_xlpm.rng<>0)*(COLUMN(_xlpm.rng)<_xlpm.lastCol)),COLUMN(_xlpm.rng),0)), _xlpm.lastVal,INDEX(B7:N7,1,_xlpm.lastCol-1), _xlpm.secondLastVal,INDEX(B7:N7,1,_xlpm.secondLastCol-1), IF(OR(_xlpm.secondLastCol=0,_xlpm.lastCol=0),"-",(_xlpm.lastVal-_xlpm.secondLastVal)/ABS(_xlpm.secondLastVal)) ),"-")} -> -0.51376147 | P7: =SUM(B7:N7) -> 1226
A8: Impressions | B8: 1568 | C8: 1879 | D8: 2210 | E8: 2066 | F8: 3259 | G8: 2320 | H8: 2324 | I8: 2304 | J8: 2222 | K8: 1967 | L8: 4553 | M8: 6425 | N8: 5374 | O8: {=IFERROR(_xlfn.LET( _xlpm.rng,B8:N8, _xlpm.lastCol,MAX(IF(ISNUMBER(_xlpm.rng)*(_xlpm.rng<>0),COLUMN(_xlpm.rng),0)), _xlpm.secondLastCol,MAX(IF((ISNUMBER(_xlpm.rng)*(_xlpm.rng<>0)*(COLUMN(_xlpm.rng)<_xlpm.lastCol)),COLUMN(_xlpm.rng),0)), _xlpm.lastVal,INDEX(B8:N8,1,_xlpm.lastCol-1), _xlpm.secondLastVal,INDEX(B8:N8,1,_xlpm.secondLastCol-1), IF(OR(_xlpm.secondLastCol=0,_xlpm.lastCol=0),"-",(_xlpm.lastVal-_xlpm.secondLastVal)/ABS(_xlpm.secondLastVal)) ),"-")} -> -0.16357977 | P8: =SUM(B8:N8) -> 38471
A9: Visits | B9: 424 | C9: 682 | D9: 591 | E9: 765 | F9: 1007 | G9: 798 | H9: 912 | I9: 832 | J9: 959 | K9: 806 | L9: 963 | M9: 1339 | N9: 1046 | O9: {=IFERROR(_xlfn.LET( _xlpm.rng,B9:N9, _xlpm.lastCol,MAX(IF(ISNUMBER(_xlpm.rng)*(_xlpm.rng<>0),COLUMN(_xlpm.rng),0)), _xlpm.secondLastCol,MAX(IF((ISNUMBER(_xlpm.rng)*(_xlpm.rng<>0)*(COLUMN(_xlpm.rng)<_xlpm.lastCol)),COLUMN(_xlpm.rng),0)), _xlpm.lastVal,INDEX(B9:N9,1,_xlpm.lastCol-1), _xlpm.secondLastVal,INDEX(B9:N9,1,_xlpm.secondLastCol-1), IF(OR(_xlpm.secondLastCol=0,_xlpm.lastCol=0),"-",(_xlpm.lastVal-_xlpm.secondLastVal)/ABS(_xlpm.secondLastVal)) ),"-")} -> -0.21882001 | P9: =SUM(B9:N9) -> 11124
A10: Petunia's Purgatory | B10: 1/4 | C10: 1/11 | D10: 1/18 | E10: 1/25 | F10: 2/1 | G10: 2/8 | H10: 2/15 | I10: 2/22 | J10: 3/1 | K10: 3/8 | L10: 3/15 | M10: 3/22 | N10: 3/29 | O10: WoW% | P10: Total
A11: Wishlists | B11: =SUMIF('Petunia''s Purgatory_WL'!$A:$A,"<="&B10,'Petunia''s Purgatory_WL'!$H:$H) -> 155 | C11: =SUMIFS('Petunia''s Purgatory_WL'!$H:$H,'Petunia''s Purgatory_WL'!$A:$A,">"&B10,'Petunia''s Purgatory_WL'!$A:$A,"<="&C10) -> 36 | D11: =SUMIFS('Petunia''s Purgatory_WL'!$H:$H,'Petunia''s Purgatory_WL'!$A:$A,">"&C10,'Petunia''s Purgatory_WL'!$A:$A,"<="&D10) -> 16 | E11: =SUMIFS('Petunia''s Purgatory_WL'!$H:$H,'Petunia''s Purgatory_WL'!$A:$A,">"&D10,'Petunia''s Purgatory_WL'!$A:$A,"<="&E10) -> 12 | F11: =SUMIFS('Petunia''s Purgatory_WL'!$H:$H,'Petunia''s Purgatory_WL'!$A:$A,">"&E10,'Petunia''s Purgatory_WL'!$A:$A,"<="&F10) -> 23 | G11: =SUMIFS('Petunia''s Purgatory_WL'!$H:$H,'Petunia''s Purgatory_WL'!$A:$A,">"&F10,'Petunia''s Purgatory_WL'!$A:$A,"<="&G10) -> 30 | H11: =SUMIFS('Petunia''s Purgatory_WL'!$H:$H,'Petunia''s Purgatory_WL'!$A:$A,">"&G10,'Petunia''s Purgatory_WL'!$A:$A,"<="&H10) -> 29 | I11: =SUMIFS('Petunia''s Purgatory_WL'!$H:$H,'Petunia''s Purgatory_WL'!$A:$A,">"&H10,'Petunia''s Purgatory_WL'!$A:$A,"<="&I10) -> 76 | J11: =SUMIFS('Petunia''s Purgatory_WL'!$H:$H,'Petunia''s Purgatory_WL'!$A:$A,">"&I10,'Petunia''s Purgatory_WL'!$A:$A,"<="&J10) -> 959 | ... N11: =SUMIFS('Petunia''s Purgatory_WL'!$H:$H,'Petunia''s Purgatory_WL'!$A:$A,">"&M10,'Petunia''s Purgatory_WL'!$A:$A,"<="&N10) -> 17 | O11: {=IFERROR(_xlfn.LET( _xlpm.rng,B11:N11, _xlpm.lastCol,MAX(IF(ISNUMBER(_xlpm.rng)*(_xlpm.rng<>0),COLUMN(_xlpm.rng),0)), _xlpm.secondLastCol,MAX(IF((ISNUMBER(_xlpm.rng)*(_xlpm.rng<>0)*(COLUMN(_xlpm.rng)<_xlpm.lastCol)),COLUMN(_xlpm.rng),0)), _xlpm.lastVal,INDEX(B11:N11,1,_xlpm.lastCol-1), _xlpm.secondLastVal,INDEX(B11:N11,1,_xlpm.secondLastCol-1), IF(OR(_xlpm.secondLastCol=0,_xlpm.lastCol=0),"-",(_xlpm.lastVal-_xlpm.secondLastVal)/ABS(_xlpm.secondLastVal)) ),"-")} -> 0.54545455 | P11: =SUM(B11:N11) -> 1425
A12: Impressions | B12: 3279 | C12: 4700 | D12: 3386 | E12: 2992 | F12: 3010 | G12: 3278 | H12: 3624 | I12: 3748 | J12: 153264 | K12: 16940 | L12: 5171 | M12: 3906 | N12: 3455 | O12: {=IFERROR(_xlfn.LET( _xlpm.rng,B12:N12, _xlpm.lastCol,MAX(IF(ISNUMBER(_xlpm.rng)*(_xlpm.rng<>0),COLUMN(_xlpm.rng),0)), _xlpm.secondLastCol,MAX(IF((ISNUMBER(_xlpm.rng)*(_xlpm.rng<>0)*(COLUMN(_xlpm.rng)<_xlpm.lastCol)),COLUMN(_xlpm.rng),0)), _xlpm.lastVal,INDEX(B12:N12,1,_xlpm.lastCol-1), _xlpm.secondLastVal,INDEX(B12:N12,1,_xlpm.secondLastCol-1), IF(OR(_xlpm.secondLastCol=0,_xlpm.lastCol=0),"-",(_xlpm.lastVal-_xlpm.secondLastVal)/ABS(_xlpm.secondLastVal)) ),"-")} -> -0.11546339 | P12: =SUM(B12:N12) -> 210753
A13: Visits | B13: 1513 | C13: 833 | D13: 795 | E13: 690 | F13: 1056 | G13: 885 | H13: 1126 | I13: 906 | J13: 5244 | K13: 1617 | L13: 1051 | M13: 1005 | N13: 4897 | O13: {=IFERROR(_xlfn.LET( _xlpm.rng,B13:N13, _xlpm.lastCol,MAX(IF(ISNUMBER(_xlpm.rng)*(_xlpm.rng<>0),COLUMN(_xlpm.rng),0)), _xlpm.secondLastCol,MAX(IF((ISNUMBER(_xlpm.rng)*(_xlpm.rng<>0)*(COLUMN(_xlpm.rng)<_xlpm.lastCol)),COLUMN(_xlpm.rng),0)), _xlpm.lastVal,INDEX(B13:N13,1,_xlpm.lastCol-1), _xlpm.secondLastVal,INDEX(B13:N13,1,_xlpm.secondLastCol-1), IF(OR(_xlpm.secondLastCol=0,_xlpm.lastCol=0),"-",(_xlpm.lastVal-_xlpm.secondLastVal)/ABS(_xlpm.secondLastVal)) ),"-")} -> 3.8726368 | P13: =SUM(B13:N13) -> 21618
A14: Fleet Breakers | B14: 1/4 | C14: 1/11 | D14: 1/18 | E14: 1/25 | F14: 2/1 | G14: 2/8 | H14: 2/15 | I14: 2/22 | J14: 3/1 | K14: 3/8 | L14: 3/15 | M14: 3/22 | N14: 3/29 | O14: WoW% | P14: Total | R14: Impressions and Visits to be added manually here.
A15: Wishlists | B15: =SUMIF(Fleetbreakers_WL!$A:$A,"<="&B14,Fleetbreakers_WL!$H:$H) -> 49 | C15: =SUMIFS(Fleetbreakers_WL!$H:$H,Fleetbreakers_WL!$A:$A,">"&B14,Fleetbreakers_WL!$A:$A,"<="&C14) -> 76 | D15: =SUMIFS(Fleetbreakers_WL!$H:$H,Fleetbreakers_WL!$A:$A,">"&C14,Fleetbreakers_WL!$A:$A,"<="&D14) -> 138 | E15: =SUMIFS(Fleetbreakers_WL!$H:$H,Fleetbreakers_WL!$A:$A,">"&D14,Fleetbreakers_WL!$A:$A,"<="&E14) -> 33 | F15: =SUMIFS(Fleetbreakers_WL!$H:$H,Fleetbreakers_WL!$A:$A,">"&E14,Fleetbreakers_WL!$A:$A,"<="&F14) -> -2 | G15: =SUMIFS(Fleetbreakers_WL!$H:$H,Fleetbreakers_WL!$A:$A,">"&F14,Fleetbreakers_WL!$A:$A,"<="&G14) -> 12 | H15: =SUMIFS(Fleetbreakers_WL!$H:$H,Fleetbreakers_WL!$A:$A,">"&G14,Fleetbreakers_WL!$A:$A,"<="&H14) -> 1 | I15: =SUMIFS(Fleetbreakers_WL!$H:$H,Fleetbreakers_WL!$A:$A,">"&H14,Fleetbreakers_WL!$A:$A,"<="&I14) -> 0 | J15: =SUMIFS(Fleetbreakers_WL!$H:$H,Fleetbreakers_WL!$A:$A,">"&I14,Fleetbreakers_WL!$A:$A,"<="&J14) -> -14 | ... N15: =SUMIFS(Fleetbreakers_WL!$H:$H,Fleetbreakers_WL!$A:$A,">"&M14,Fleetbreakers_WL!$A:$A,"<="&N14) -> -2 | O15: {=IFERROR(_xlfn.LET( _xlpm.rng,B15:N15, _xlpm.lastCol,MAX(IF(ISNUMBER(_xlpm.rng)*(_xlpm.rng<>0),COLUMN(_xlpm.rng),0)), _xlpm.secondLastCol,MAX(IF((ISNUMBER(_xlpm.rng)*(_xlpm.rng<>0)*(COLUMN(_xlpm.rng)<_xlpm.lastCol)),COLUMN(_xlpm.rng),0)), _xlpm.lastVal,INDEX(B15:N15,1,_xlpm.lastCol-1), _xlpm.secondLastVal,INDEX(B15:N15,1,_xlpm.secondLastCol-1), IF(OR(_xlpm.secondLastCol=0,_xlpm.lastCol=0),"-",(_xlpm.lastVal-_xlpm.secondLastVal)/ABS(_xlpm.secondLastVal)) ),"-")} -> 0.6 | P15: =SUM(B15:N15) -> 292
A16: Impressions | B16: 5095 | C16: 6399 | D16: 5490 | E16: 5392 | F16: 5225 | G16: 4806 | H16: 4560 | I16: 4282 | J16: 5673 | K16: 4376 | L16: 3950 | M16: 5167 | N16: 4403 | O16: {=IFERROR(_xlfn.LET( _xlpm.rng,B16:N16, _xlpm.lastCol,MAX(IF(ISNUMBER(_xlpm.rng)*(_xlpm.rng<>0),COLUMN(_xlpm.rng),0)), _xlpm.secondLastCol,MAX(IF((ISNUMBER(_xlpm.rng)*(_xlpm.rng<>0)*(COLUMN(_xlpm.rng)<_xlpm.lastCol)),COLUMN(_xlpm.rng),0)), _xlpm.lastVal,INDEX(B16:N16,1,_xlpm.lastCol-1), _xlpm.secondLastVal,INDEX(B16:N16,1,_xlpm.secondLastCol-1), IF(OR(_xlpm.secondLastCol=0,_xlpm.lastCol=0),"-",(_xlpm.lastVal-_xlpm.secondLastVal)/ABS(_xlpm.secondLastVal)) ),"-")} -> -0.14786143 | P16: =SUM(B16:N16) -> 64818
A17: Visits | B17: 1107 | C17: 2049 | D17: 1631 | E17: 889 | F17: 726 | G17: 705 | H17: 769 | I17: 704 | J17: 906 | K17: 799 | L17: 662 | M17: 751 | N17: 707 | O17: {=IFERROR(_xlfn.LET( _xlpm.rng,B17:N17, _xlpm.lastCol,MAX(IF(ISNUMBER(_xlpm.rng)*(_xlpm.rng<>0),COLUMN(_xlpm.rng),0)), _xlpm.secondLastCol,MAX(IF((ISNUMBER(_xlpm.rng)*(_xlpm.rng<>0)*(COLUMN(_xlpm.rng)<_xlpm.lastCol)),COLUMN(_xlpm.rng),0)), _xlpm.lastVal,INDEX(B17:N17,1,_xlpm.lastCol-1), _xlpm.secondLastVal,INDEX(B17:N17,1,_xlpm.secondLastCol-1), IF(OR(_xlpm.secondLastCol=0,_xlpm.lastCol=0),"-",(_xlpm.lastVal-_xlpm.secondLastVal)/ABS(_xlpm.secondLastVal)) ),"-")} -> -0.058588549 | P17: =SUM(B17:N17) -> 12405
A18: Quarter 2 | P18: Quarter Totals
A19: Taival | B19: 4/5 | C19: 4/12 | D19: 4/19 | E19: 4/26 | F19: 5/3 | G19: 5/10 | H19: 5/16 | I19: 5/23 | J19: 5/30 | K19: 6/6 | L19: 6/13 | M19: 6/20 | N19: 6/27 | O19: WoW% | P19: Total
A20: Wishlists | B20: =SUMIFS(Taival_WL!$H:$H,Taival_WL!$A:$A,">"&N2,Taival_WL!$A:$A,"<="&B19) -> 249 | C20: =SUMIFS(Taival_WL!$H:$H,Taival_WL!$A:$A,">"&B19,Taival_WL!$A:$A,"<="&C19) -> 363 | D20: =SUMIFS(Taival_WL!$H:$H,Taival_WL!$A:$A,">"&C19,Taival_WL!$A:$A,"<="&D19) -> 668 | E20: =SUMIFS(Taival_WL!$H:$H,Taival_WL!$A:$A,">"&D19,Taival_WL!$A:$A,"<="&E19) -> 3186 | F20: =SUMIFS(Taival_WL!$H:$H,Taival_WL!$A:$A,">"&E19,Taival_WL!$A:$A,"<="&F19) -> 827 | G20: =SUMIFS(Taival_WL!$H:$H,Taival_WL!$A:$A,">"&F19,Taival_WL!$A:$A,"<="&G19) -> 0 | H20: =SUMIFS(Taival_WL!$H:$H,Taival_WL!$A:$A,">"&G19,Taival_WL!$A:$A,"<="&H19) -> 0 | I20: =SUMIFS(Taival_WL!$H:$H,Taival_WL!$A:$A,">"&H19,Taival_WL!$A:$A,"<="&I19) -> 0 | J20: =SUMIFS(Taival_WL!$H:$H,Taival_WL!$A:$A,">"&I19,Taival_WL!$A:$A,"<="&J19) -> 0 | ... N20: =SUMIFS(Taival_WL!$H:$H,Taival_WL!$A:$A,">"&M19,Taival_WL!$A:$A,"<="&N19) -> 0 | O20: {=IFERROR(_xlfn.LET( _xlpm.rng,B20:N20, _xlpm.lastCol,MAX(IF(ISNUMBER(_xlpm.rng)*(_xlpm.rng<>0),COLUMN(_xlpm.rng),0)), _xlpm.secondLastCol,MAX(IF((ISNUMBER(_xlpm.rng)*(_xlpm.rng<>0)*(COLUMN(_xlpm.rng)<_xlpm.lastCol)),COLUMN(_xlpm.rng),0)), _xlpm.lastVal,INDEX(B20:N20,1,_xlpm.lastCol-1), _xlpm.secondLastVal,INDEX(B20:N20,1,_xlpm.secondLastCol-1), IF(OR(_xlpm.secondLastCol=0,_xlpm.lastCol=0),"-",(_xlpm.lastVal-_xlpm.secondLastVal)/ABS(_xlpm.secondLastVal)) ),"-")} -> -0.74042687 | P20: =SUM(B20:N20) -> 5293
A21: Impressions | B21: 3697 | C21: 4970 | D21: 14388 | E21: 16730 | F21: 14879 | G21: 0 | H21: 0 | I21: 0 | J21: 0 | K21: 0 | L21: 0 | M21: 0 | N21: 0 | O21: {=IFERROR(_xlfn.LET( _xlpm.rng,B21:N21, _xlpm.lastCol,MAX(IF(ISNUMBER(_xlpm.rng)*(_xlpm.rng<>0),COLUMN(_xlpm.rng),0)), _xlpm.secondLastCol,MAX(IF((ISNUMBER(_xlpm.rng)*(_xlpm.rng<>0)*(COLUMN(_xlpm.rng)<_xlpm.lastCol)),COLUMN(_xlpm.rng),0)), _xlpm.lastVal,INDEX(B21:N21,1,_xlpm.lastCol-1), _xlpm.secondLastVal,INDEX(B21:N21,1,_xlpm.secondLastCol-1), IF(OR(_xlpm.secondLastCol=0,_xlpm.lastCol=0),"-",(_xlpm.lastVal-_xlpm.secondLastVal)/ABS(_xlpm.secondLastVal)) ),"-")} -> -0.11063957 | P21: =SUM(B21:N21) -> 54664
A22: Visits | B22: 1276 | C22: 2020 | D22: 2147 | E22: 14587 | F22: 6087 | G22: 0 | H22: 0 | I22: 0 | J22: 0 | K22: 0 | L22: 0 | M22: 0 | N22: 0 | O22: {=IFERROR(_xlfn.LET( _xlpm.rng,B22:N22, _xlpm.lastCol,MAX(IF(ISNUMBER(_xlpm.rng)*(_xlpm.rng<>0),COLUMN(_xlpm.rng),0)), _xlpm.secondLastCol,MAX(IF((ISNUMBER(_xlpm.rng)*(_xlpm.rng<>0)*(COLUMN(_xlpm.rng)<_xlpm.lastCol)),COLUMN(_xlpm.rng),0)), _xlpm.lastVal,INDEX(B22:N22,1,_xlpm.lastCol-1), _xlpm.secondLastVal,INDEX(B22:N22,1,_xlpm.secondLastCol-1), IF(OR(_xlpm.secondLastCol=0,_xlpm.lastCol=0),"-",(_xlpm.lastVal-_xlpm.secondLastVal)/ABS(_xlpm.secondLastVal)) ),"-")} -> -0.58271063 | P22: =SUM(B22:N22) -> 26117
A23: Colossus - Eternal Blight | B23: 4/5 | C23: 4/12 | D23: 4/19 | E23: 4/26 | F23: 5/3 | G23: 5/10 | H23: 5/16 | I23: 5/23 | J23: 5/30 | K23: 6/6 | L23: 6/13 | M23: 6/20 | N23: 6/27 | O23: WoW% | P23: Total
A24: Wishlists | B24: =SUMIFS('Colossus - Eternal Blight_WL'!$H:$H,'Colossus - Eternal Blight_WL'!$A:$A,">"&N6,'Colossus - Eternal Blight_WL'!$A:$A,"<="&B23) -> 83 | C24: =SUMIFS('Colossus - Eternal Blight_WL'!$H:$H,'Colossus - Eternal Blight_WL'!$A:$A,">"&B23,'Colossus - Eternal Blight_WL'!$A:$A,"<="&C23) -> 92 | D24: =SUMIFS('Colossus - Eternal Blight_WL'!$H:$H,'Colossus - Eternal Blight_WL'!$A:$A,">"&C23,'Colossus - Eternal Blight_WL'!$A:$A,"<="&D23) -> 295 | E24: =SUMIFS('Colossus - Eternal Blight_WL'!$H:$H,'Colossus - Eternal Blight_WL'!$A:$A,">"&D23,'Colossus - Eternal Blight_WL'!$A:$A,"<="&E23) -> 514 | F24: =SUMIFS('Colossus - Eternal Blight_WL'!$H:$H,'Colossus - Eternal Blight_WL'!$A:$A,">"&E23,'Colossus - Eternal Blight_WL'!$A:$A,"<="&F23) -> 272 | G24: =SUMIFS('Colossus - Eternal Blight_WL'!$H:$H,'Colossus - Eternal Blight_WL'!$A:$A,">"&F23,'Colossus - Eternal Blight_WL'!$A:$A,"<="&G23) -> 0 | H24: =SUMIFS('Colossus - Eternal Blight_WL'!$H:$H,'Colossus - Eternal Blight_WL'!$A:$A,">"&G23,'Colossus - Eternal Blight_WL'!$A:$A,"<="&H23) -> 0 | I24: =SUMIFS('Colossus - Eternal Blight_WL'!$H:$H,'Colossus - Eternal Blight_WL'!$A:$A,">"&H23,'Colossus - Eternal Blight_WL'!$A:$A,"<="&I23) -> 0 | J24: =SUMIFS('Colossus - Eternal Blight_WL'!$H:$H,'Colossus - Eternal Blight_WL'!$A:$A,">"&I23,'Colossus - Eternal Blight_WL'!$A:$A,"<="&J23) -> 0 | ... N24: =SUMIFS('Colossus - Eternal Blight_WL'!$H:$H,'Colossus - Eternal Blight_WL'!$A:$A,">"&M23,'Colossus - Eternal Blight_WL'!$A:$A,"<="&N23) -> 0 | O24: {=IFERROR(_xlfn.LET( _xlpm.rng,B24:N24, _xlpm.lastCol,MAX(IF(ISNUMBER(_xlpm.rng)*(_xlpm.rng<>0),COLUMN(_xlpm.rng),0)), _xlpm.secondLastCol,MAX(IF((ISNUMBER(_xlpm.rng)*(_xlpm.rng<>0)*(COLUMN(_xlpm.rng)<_xlpm.lastCol)),COLUMN(_xlpm.rng),0)), _xlpm.lastVal,INDEX(B24:N24,1,_xlpm.lastCol-1), _xlpm.secondLastVal,INDEX(B24:N24,1,_xlpm.secondLastCol-1), IF(OR(_xlpm.secondLastCol=0,_xlpm.lastCol=0),"-",(_xlpm.lastVal-_xlpm.secondLastVal)/ABS(_xlpm.secondLastVal)) ),"-")} -> -0.47081712 | P24: =SUM(B24:N24) -> 1256
A25: Impressions | B25: 3631 | C25: 3253 | D25: 14258 | E25: 6946 | F25: 7164 | G25: 0 | H25: 0 | I25: 0 | J25: 0 | K25: 0 | L25: 0 | M25: 0 | N25: 0 | O25: {=IFERROR(_xlfn.LET( _xlpm.rng,B25:N25, _xlpm.lastCol,MAX(IF(ISNUMBER(_xlpm.rng)*(_xlpm.rng<>0),COLUMN(_xlpm.rng),0)), _xlpm.secondLastCol,MAX(IF((ISNUMBER(_xlpm.rng)*(_xlpm.rng<>0)*(COLUMN(_xlpm.rng)<_xlpm.lastCol)),COLUMN(_xlpm.rng),0)), _xlpm.lastVal,INDEX(B25:N25,1,_xlpm.lastCol-1), _xlpm.secondLastVal,INDEX(B25:N25,1,_xlpm.secondLastCol-1), IF(OR(_xlpm.secondLastCol=0,_xlpm.lastCol=0),"-",(_xlpm.lastVal-_xlpm.secondLastVal)/ABS(_xlpm.secondLastVal)) ),"-")} -> 0.03138497 | P25: =SUM(B25:N25) -> 35252
A26: Visits | B26: 887 | C26: 839 | D26: 1232 | E26: 1542 | F26: 1502 | G26: 0 | H26: 0 | I26: 0 | J26: 0 | K26: 0 | L26: 0 | M26: 0 | N26: 0 | O26: {=IFERROR(_xlfn.LET( _xlpm.rng,B26:N26, _xlpm.lastCol,MAX(IF(ISNUMBER(_xlpm.rng)*(_xlpm.rng<>0),COLUMN(_xlpm.rng),0)), _xlpm.secondLastCol,MAX(IF((ISNUMBER(_xlpm.rng)*(_xlpm.rng<>0)*(COLUMN(_xlpm.rng)<_xlpm.lastCol)),COLUMN(_xlpm.rng),0)), _xlpm.lastVal,INDEX(B26:N26,1,_xlpm.lastCol-1), _xlpm.secondLastVal,INDEX(B26:N26,1,_xlpm.secondLastCol-1), IF(OR(_xlpm.secondLastCol=0,_xlpm.lastCol=0),"-",(_xlpm.lastVal-_xlpm.secondLastVal)/ABS(_xlpm.secondLastVal)) ),"-")} -> -0.025940337 | P26: =SUM(B26:N26) -> 6002
A27: Petunia's Purgatory | B27: 4/5 | C27: 4/12 | D27: 4/19 | E27: 4/26 | F27: 5/3 | G27: 5/10 | H27: 5/16 | I27: 5/23 | J27: 5/30 | K27: 6/6 | L27: 6/13 | M27: 6/20 | N27: 6/27 | O27: WoW% | P27: Total
A28: Wishlists | B28: =SUMIFS('Petunia''s Purgatory_WL'!$H:$H,'Petunia''s Purgatory_WL'!$A:$A,">"&N10,'Petunia''s Purgatory_WL'!$A:$A,"<="&B27) -> 41 | C28: =SUMIFS('Petunia''s Purgatory_WL'!$H:$H,'Petunia''s Purgatory_WL'!$A:$A,">"&B27,'Petunia''s Purgatory_WL'!$A:$A,"<="&C27) -> 35 | D28: =SUMIFS('Petunia''s Purgatory_WL'!$H:$H,'Petunia''s Purgatory_WL'!$A:$A,">"&C27,'Petunia''s Purgatory_WL'!$A:$A,"<="&D27) -> 28 | E28: =SUMIFS('Petunia''s Purgatory_WL'!$H:$H,'Petunia''s Purgatory_WL'!$A:$A,">"&D27,'Petunia''s Purgatory_WL'!$A:$A,"<="&E27) -> 26 | F28: =SUMIFS('Petunia''s Purgatory_WL'!$H:$H,'Petunia''s Purgatory_WL'!$A:$A,">"&E27,'Petunia''s Purgatory_WL'!$A:$A,"<="&F27) -> 14 | G28: =SUMIFS('Petunia''s Purgatory_WL'!$H:$H,'Petunia''s Purgatory_WL'!$A:$A,">"&F27,'Petunia''s Purgatory_WL'!$A:$A,"<="&G27) -> 0 | H28: =SUMIFS('Petunia''s Purgatory_WL'!$H:$H,'Petunia''s Purgatory_WL'!$A:$A,">"&G27,'Petunia''s Purgatory_WL'!$A:$A,"<="&H27) -> 0 | I28: =SUMIFS('Petunia''s Purgatory_WL'!$H:$H,'Petunia''s Purgatory_WL'!$A:$A,">"&H27,'Petunia''s Purgatory_WL'!$A:$A,"<="&I27) -> 0 | J28: =SUMIFS('Petunia''s Purgatory_WL'!$H:$H,'Petunia''s Purgatory_WL'!$A:$A,">"&I27,'Petunia''s Purgatory_WL'!$A:$A,"<="&J27) -> 0 | ... N28: =SUMIFS('Petunia''s Purgatory_WL'!$H:$H,'Petunia''s Purgatory_WL'!$A:$A,">"&M27,'Petunia''s Purgatory_WL'!$A:$A,"<="&N27) -> 0 | O28: {=IFERROR(_xlfn.LET( _xlpm.rng,B28:N28, _xlpm.lastCol,MAX(IF(ISNUMBER(_xlpm.rng)*(_xlpm.rng<>0),COLUMN(_xlpm.rng),0)), _xlpm.secondLastCol,MAX(IF((ISNUMBER(_xlpm.rng)*(_xlpm.rng<>0)*(COLUMN(_xlpm.rng)<_xlpm.lastCol)),COLUMN(_xlpm.rng),0)), _xlpm.lastVal,INDEX(B28:N28,1,_xlpm.lastCol-1), _xlpm.secondLastVal,INDEX(B28:N28,1,_xlpm.secondLastCol-1), IF(OR(_xlpm.secondLastCol=0,_xlpm.lastCol=0),"-",(_xlpm.lastVal-_xlpm.secondLastVal)/ABS(_xlpm.secondLastVal)) ),"-")} -> -0.46153846 | P28: =SUM(B28:N28) -> 144
A29: Impressions | B29: 3364 | C29: 3463 | D29: 2997 | E29: 2844 | F29: 2837 | G29: 0 | H29: 0 | I29: 0 | J29: 0 | K29: 0 | L29: 0 | M29: 0 | N29: 0 | O29: {=IFERROR(_xlfn.LET( _xlpm.rng,B29:N29, _xlpm.lastCol,MAX(IF(ISNUMBER(_xlpm.rng)*(_xlpm.rng<>0),COLUMN(_xlpm.rng),0)), _xlpm.secondLastCol,MAX(IF((ISNUMBER(_xlpm.rng)*(_xlpm.rng<>0)*(COLUMN(_xlpm.rng)<_xlpm.lastCol)),COLUMN(_xlpm.rng),0)), _xlpm.lastVal,INDEX(B29:N29,1,_xlpm.lastCol-1), _xlpm.secondLastVal,INDEX(B29:N29,1,_xlpm.secondLastCol-1), IF(OR(_xlpm.secondLastCol=0,_xlpm.lastCol=0),"-",(_xlpm.lastVal-_xlpm.secondLastVal)/ABS(_xlpm.secondLastVal)) ),"-")} -> -0.0024613221 | P29: =SUM(B29:N29) -> 15505
A30: Visits | B30: 5782 | C30: 7678 | D30: 5615 | E30: 5242 | F30: 7094 | G30: 0 | H30: 0 | I30: 0 | J30: 0 | K30: 0 | L30: 0 | M30: 0 | N30: 0 | O30: {=IFERROR(_xlfn.LET( _xlpm.rng,B30:N30, _xlpm.lastCol,MAX(IF(ISNUMBER(_xlpm.rng)*(_xlpm.rng<>0),COLUMN(_xlpm.rng),0)), _xlpm.secondLastCol,MAX(IF((ISNUMBER(_xlpm.rng)*(_xlpm.rng<>0)*(COLUMN(_xlpm.rng)<_xlpm.lastCol)),COLUMN(_xlpm.rng),0)), _xlpm.lastVal,INDEX(B30:N30,1,_xlpm.lastCol-1), _xlpm.secondLastVal,INDEX(B30:N30,1,_xlpm.secondLastCol-1), IF(OR(_xlpm.secondLastCol=0,_xlpm.lastCol=0),"-",(_xlpm.lastVal-_xlpm.secondLastVal)/ABS(_xlpm.secondLastVal)) ),"-")} -> 0.35330027 | P30: =SUM(B30:N30) -> 31411
A31: Fleet Breakers | B31: 4/5 | C31: 4/12 | D31: 4/19 | E31: 4/26 | F31: 5/3 | G31: 5/10 | H31: 5/17 | I31: 5/24 | J31: 5/31 | K31: 6/7 | L31: 6/14 | M31: 6/21 | N31: 6/28 | O31: WoW% | P31: Total
A32: Wishlists | B32: =SUMIFS(Fleetbreakers_WL!$H:$H,Fleetbreakers_WL!$A:$A,">"&N14,Fleetbreakers_WL!$A:$A,"<="&B31) -> 8 | C32: =SUMIFS(Fleetbreakers_WL!$H:$H,Fleetbreakers_WL!$A:$A,">"&B31,Fleetbreakers_WL!$A:$A,"<="&C31) -> 8 | D32: =SUMIFS(Fleetbreakers_WL!$H:$H,Fleetbreakers_WL!$A:$A,">"&C31,Fleetbreakers_WL!$A:$A,"<="&D31) -> -4 | E32: =SUMIFS(Fleetbreakers_WL!$H:$H,Fleetbreakers_WL!$A:$A,">"&D31,Fleetbreakers_WL!$A:$A,"<="&E31) -> -2 | F32: =SUMIFS(Fleetbreakers_WL!$H:$H,Fleetbreakers_WL!$A:$A,">"&E31,Fleetbreakers_WL!$A:$A,"<="&F31) -> 15 | G32: =SUMIFS(Fleetbreakers_WL!$H:$H,Fleetbreakers_WL!$A:$A,">"&F31,Fleetbreakers_WL!$A:$A,"<="&G31) -> 0 | H32: =SUMIFS(Fleetbreakers_WL!$H:$H,Fleetbreakers_WL!$A:$A,">"&G31,Fleetbreakers_WL!$A:$A,"<="&H31) -> 0 | I32: =SUMIFS(Fleetbreakers_WL!$H:$H,Fleetbreakers_WL!$A:$A,">"&H31,Fleetbreakers_WL!$A:$A,"<="&I31) -> 0 | J32: =SUMIFS(Fleetbreakers_WL!$H:$H,Fleetbreakers_WL!$A:$A,">"&I31,Fleetbreakers_WL!$A:$A,"<="&J31) -> 0 | ... N32: =SUMIFS(Fleetbreakers_WL!$H:$H,Fleetbreakers_WL!$A:$A,">"&M31,Fleetbreakers_WL!$A:$A,"<="&N31) -> 0 | O32: {=IFERROR(_xlfn.LET( _xlpm.rng,B32:N32, _xlpm.lastCol,MAX(IF(ISNUMBER(_xlpm.rng)*(_xlpm.rng<>0),COLUMN(_xlpm.rng),0)), _xlpm.secondLastCol,MAX(IF((ISNUMBER(_xlpm.rng)*(_xlpm.rng<>0)*(COLUMN(_xlpm.rng)<_xlpm.lastCol)),COLUMN(_xlpm.rng),0)), _xlpm.lastVal,INDEX(B32:N32,1,_xlpm.lastCol-1), _xlpm.secondLastVal,INDEX(B32:N32,1,_xlpm.secondLastCol-1), IF(OR(_xlpm.secondLastCol=0,_xlpm.lastCol=0),"-",(_xlpm.lastVal-_xlpm.secondLastVal)/ABS(_xlpm.secondLastVal)) ),"-")} -> 8.5 | P32: =SUM(B32:N32) -> 25
A33: Impressions | B33: 3652 | C33: 3825 | D33: 5291 | E33: 4857 | F33: 6270 | G33: 0 | H33: 0 | I33: 0 | J33: 0 | K33: 0 | L33: 0 | M33: 0 | N33: 0 | O33: {=IFERROR(_xlfn.LET( _xlpm.rng,B33:N33, _xlpm.lastCol,MAX(IF(ISNUMBER(_xlpm.rng)*(_xlpm.rng<>0),COLUMN(_xlpm.rng),0)), _xlpm.secondLastCol,MAX(IF((ISNUMBER(_xlpm.rng)*(_xlpm.rng<>0)*(COLUMN(_xlpm.rng)<_xlpm.lastCol)),COLUMN(_xlpm.rng),0)), _xlpm.lastVal,INDEX(B33:N33,1,_xlpm.lastCol-1), _xlpm.secondLastVal,INDEX(B33:N33,1,_xlpm.secondLastCol-1), IF(OR(_xlpm.secondLastCol=0,_xlpm.lastCol=0),"-",(_xlpm.lastVal-_xlpm.secondLastVal)/ABS(_xlpm.secondLastVal)) ),"-")} -> 0.29092032 | P33: =SUM(B33:N33) -> 23895
A34: Visits | B34: 783 | C34: 790 | D34: 614 | E34: 891 | F34: 1106 | G34: 0 | H34: 0 | I34: 0 | J34: 0 | K34: 0 | L34: 0 | M34: 0 | N34: 0 | O34: {=IFERROR(_xlfn.LET( _xlpm.rng,B34:N34, _xlpm.lastCol,MAX(IF(ISNUMBER(_xlpm.rng)*(_xlpm.rng<>0),COLUMN(_xlpm.rng),0)), _xlpm.secondLastCol,MAX(IF((ISNUMBER(_xlpm.rng)*(_xlpm.rng<>0)*(COLUMN(_xlpm.rng)<_xlpm.lastCol)),COLUMN(_xlpm.rng),0)), _xlpm.lastVal,INDEX(B34:N34,1,_xlpm.lastCol-1), _xlpm.secondLastVal,INDEX(B34:N34,1,_xlpm.secondLastCol-1), IF(OR(_xlpm.secondLastCol=0,_xlpm.lastCol=0),"-",(_xlpm.lastVal-_xlpm.secondLastVal)/ABS(_xlpm.secondLastVal)) ),"-")} -> 0.24130191 | P34: =SUM(B34:N34) -> 4184
A35: Quarter 3 | P35: Quarter Totals
A36: Taival | B36: 7/4 | C36: 7/11 | D36: 7/18 | E36: 7/25 | F36: 8/1 | G36: 8/8 | H36: 8/15 | I36: 8/22 | J36: 8/29 | K36: 9/5 | L36: 9/12 | M36: 9/19 | N36: 9/26 | O36: WoW% | P36: Total
A37: Wishlists | B37: =SUMIF(Taival_WL!$A:$A,"<="&B36,Taival_WL!$H:$H)-SUMIF(Taival_WL!$A:$A,"<="&N19,Taival_WL!$H:$H) -> 0 | C37: =SUMIFS(Taival_WL!$H:$H,Taival_WL!$A:$A,">"&B36,Taival_WL!$A:$A,"<="&C36) -> 0 | D37: =SUMIFS(Taival_WL!$H:$H,Taival_WL!$A:$A,">"&C36,Taival_WL!$A:$A,"<="&D36) -> 0 | E37: =SUMIFS(Taival_WL!$H:$H,Taival_WL!$A:$A,">"&D36,Taival_WL!$A:$A,"<="&E36) -> 0 | F37: =SUMIFS(Taival_WL!$H:$H,Taival_WL!$A:$A,">"&E36,Taival_WL!$A:$A,"<="&F36) -> 0 | G37: =SUMIFS(Taival_WL!$H:$H,Taival_WL!$A:$A,">"&F36,Taival_WL!$A:$A,"<="&G36) -> 0 | H37: =SUMIFS(Taival_WL!$H:$H,Taival_WL!$A:$A,">"&G36,Taival_WL!$A:$A,"<="&H36) -> 0 | I37: =SUMIFS(Taival_WL!$H:$H,Taival_WL!$A:$A,">"&H36,Taival_WL!$A:$A,"<="&I36) -> 0 | J37: =SUMIFS(Taival_WL!$H:$H,Taival_WL!$A:$A,">"&I36,Taival_WL!$A:$A,"<="&J36) -> 0 | ... N37: =SUMIFS(Taival_WL!$H:$H,Taival_WL!$A:$A,">"&M36,Taival_WL!$A:$A,"<="&N36) -> 0 | O37: {=IFERROR(_xlfn.LET( _xlpm.rng,B37:N37, _xlpm.lastCol,MAX(IF(ISNUMBER(_xlpm.rng)*(_xlpm.rng<>0),COLUMN(_xlpm.rng),0)), _xlpm.secondLastCol,MAX(IF((ISNUMBER(_xlpm.rng)*(_xlpm.rng<>0)*(COLUMN(_xlpm.rng)<_xlpm.lastCol)),COLUMN(_xlpm.rng),0)), _xlpm.lastVal,INDEX(B37:N37,1,_xlpm.lastCol-1), _xlpm.secondLastVal,INDEX(B37:N37,1,_xlpm.secondLastCol-1), IF(OR(_xlpm.secondLastCol=0,_xlpm.lastCol=0),"-",(_xlpm.lastVal-_xlpm.secondLastVal)/ABS(_xlpm.secondLastVal)) ),"-")} -> - | P37: =SUM(B37:N37) -> 0
A38: Impressions | B38: 0 | C38: 0 | D38: 0 | E38: 0 | F38: 0 | G38: 0 | H38: 0 | I38: 0 | J38: 0 | K38: 0 | L38: 0 | M38: 0 | N38: 0 | O38: {=IFERROR(_xlfn.LET( _xlpm.rng,B38:N38, _xlpm.lastCol,MAX(IF(ISNUMBER(_xlpm.rng)*(_xlpm.rng<>0),COLUMN(_xlpm.rng),0)), _xlpm.secondLastCol,MAX(IF((ISNUMBER(_xlpm.rng)*(_xlpm.rng<>0)*(COLUMN(_xlpm.rng)<_xlpm.lastCol)),COLUMN(_xlpm.rng),0)), _xlpm.lastVal,INDEX(B38:N38,1,_xlpm.lastCol-1), _xlpm.secondLastVal,INDEX(B38:N38,1,_xlpm.secondLastCol-1), IF(OR(_xlpm.secondLastCol=0,_xlpm.lastCol=0),"-",(_xlpm.lastVal-_xlpm.secondLastVal)/ABS(_xlpm.secondLastVal)) ),"-")} -> - | P38: =SUM(B38:N38) -> 0
A39: Visits | B39: 0 | C39: 0 | D39: 0 | E39: 0 | F39: 0 | G39: 0 | H39: 0 | I39: 0 | J39: 0 | K39: 0 | L39: 0 | M39: 0 | N39: 0 | O39: {=IFERROR(_xlfn.LET( _xlpm.rng,B39:N39, _xlpm.lastCol,MAX(IF(ISNUMBER(_xlpm.rng)*(_xlpm.rng<>0),COLUMN(_xlpm.rng),0)), _xlpm.secondLastCol,MAX(IF((ISNUMBER(_xlpm.rng)*(_xlpm.rng<>0)*(COLUMN(_xlpm.rng)<_xlpm.lastCol)),COLUMN(_xlpm.rng),0)), _xlpm.lastVal,INDEX(B39:N39,1,_xlpm.lastCol-1), _xlpm.secondLastVal,INDEX(B39:N39,1,_xlpm.secondLastCol-1), IF(OR(_xlpm.secondLastCol=0,_xlpm.lastCol=0),"-",(_xlpm.lastVal-_xlpm.secondLastVal)/ABS(_xlpm.secondLastVal)) ),"-")} -> - | P39: =SUM(B39:N39) -> 0
A40: Colossus - Eternal Blight | B40: 7/4 | C40: 7/11 | D40: 7/18 | E40: 7/25 | F40: 8/1 | G40: 8/8 | H40: 8/15 | I40: 8/22 | J40: 8/29 | K40: 9/5 | L40: 9/12 | M40: 9/19 | N40: 9/26 | O40: WoW% | P40: Total
...

Sheet Taival_WL
A1: DateLocal | B1: Game | C1: Adds | D1: Deletes | E1: Purchases And Activations | F1: Gifts | G1: Net Wishlist | H1: Weekly Net | I1: Monthly Net
A2: 46023 | B2: Taival | C2: 6 | D2: 2 | E2: 0 | F2: 0 | G2: =SUM(F2,E2,C2-D2) -> 4 | H2: =SUM(G2:G5) -> 4 | I2: =SUM(G2:G60) -> 47
A3: 46024 | B3: Taival | C3: 2 | D3: 4 | E3: 0 | F3: 0 | G3: =SUM(F3,E3,C3-D3) -> -2
A4: 46025 | B4: Taival | C4: 4 | D4: 0 | E4: 0 | F4: 0 | G4: =SUM(F4,E4,C4-D4) -> 4 | K4: Data CSV. To be added here
A5: 46026 | B5: Taival | C5: 1 | D5: 3 | E5: 0 | F5: 0 | G5: =SUM(F5,E5,C5-D5) -> -2
A6: 46027 | B6: Taival | C6: 2 | D6: 0 | E6: 0 | F6: 0 | G6: =SUM(F6,E6,C6-D6) -> 2 | H6: =SUM(G6:G12) -> 2
A7: 46028 | B7: Taival | C7: 2 | D7: 2 | E7: 0 | F7: 0 | G7: =SUM(F7,E7,C7-D7) -> 0
A8: 46029 | B8: Taival | C8: 0 | D8: 0 | E8: 0 | F8: 0 | G8: =SUM(F8,E8,C8-D8) -> 0
A9: 46030 | B9: Taival | C9: 2 | D9: 2 | E9: 0 | F9: 0 | G9: =SUM(F9,E9,C9-D9) -> 0
A10: 46031 | B10: Taival | C10: 1 | D10: 1 | E10: 0 | F10: 0 | G10: =SUM(F10,E10,C10-D10) -> 0
A11: 46032 | B11: Taival | C11: 2 | D11: 0 | E11: 0 | F11: 0 | G11: =SUM(F11,E11,C11-D11) -> 2
A12: 46033 | B12: Taival | C12: 0 | D12: 2 | E12: 0 | F12: 0 | G12: =SUM(F12,E12,C12-D12) -> -2
A13: 46034 | B13: Taival | C13: 2 | D13: 4 | E13: 0 | F13: 0 | G13: =SUM(F13,E13,C13-D13) -> -2 | H13: =SUM(G13:G19) -> 16
A14: 46035 | B14: Taival | C14: 4 | D14: 1 | E14: 0 | F14: 0 | G14: =SUM(F14,E14,C14-D14) -> 3
A15: 46036 | B15: Taival | C15: 4 | D15: 0 | E15: 0 | F15: 0 | G15: =SUM(F15,E15,C15-D15) -> 4
A16: 46037 | B16: Taival | C16: 4 | D16: 1 | E16: 0 | F16: 0 | G16: =SUM(F16,E16,C16-D16) -> 3
A17: 46038 | B17: Taival | C17: 2 | D17: 1 | E17: 0 | F17: 0 | G17: =SUM(F17,E17,C17-D17) -> 1
A18: 46039 | B18: Taival | C18: 6 | D18: 2 | E18: 0 | F18: 0 | G18: =SUM(F18,E18,C18-D18) -> 4
A19: 46040 | B19: Taival | C19: 7 | D19: 4 | E19: 0 | F19: 0 | G19: =SUM(F19,E19,C19-D19) -> 3
A20: 46041 | B20: Taival | C20: 2 | D20: 2 | E20: 0 | F20: 0 | G20: =SUM(F20,E20,C20-D20) -> 0 | H20: =SUM(G20:G26) -> 0
A21: 46042 | B21: Taival | C21: 4 | D21: 4 | E21: 0 | F21: 0 | G21: =SUM(F21,E21,C21-D21) -> 0
A22: 46043 | B22: Taival | C22: 1 | D22: 2 | E22: 0 | F22: 0 | G22: =SUM(F22,E22,C22-D22) -> -1
A23: 46044 | B23: Taival | C23: 2 | D23: 0 | E23: 0 | F23: 0 | G23: =SUM(F23,E23,C23-D23) -> 2
A24: 46045 | B24: Taival | C24: 1 | D24: 0 | E24: 0 | F24: 0 | G24: =SUM(F24,E24,C24-D24) -> 1
A25: 46046 | B25: Taival | C25: 2 | D25: 2 | E25: 0 | F25: 0 | G25: =SUM(F25,E25,C25-D25) -> 0
A26: 46047 | B26: Taival | C26: 2 | D26: 4 | E26: 0 | F26: 0 | G26: =SUM(F26,E26,C26-D26) -> -2
A27: 46048 | B27: Taival | C27: 1 | D27: 1 | E27: 0 | F27: 0 | G27: =SUM(F27,E27,C27-D27) -> 0 | H27: =SUM(G27:G33) -> -2
A28: 46049 | B28: Taival | C28: 3 | D28: 2 | E28: 1 | F28: 0 | G28: =SUM(F28,E28,C28-D28) -> 2
A29: 46050 | B29: Taival | C29: 2 | D29: 2 | E29: 0 | F29: 0 | G29: =SUM(F29,E29,C29-D29) -> 0
A30: 46051 | B30: Taival | C30: 2 | D30: 2 | E30: 0 | F30: 0 | G30: =SUM(F30,E30,C30-D30) -> 0
A31: 46052 | B31: Taival | C31: 0 | D31: 3 | E31: 0 | F31: 0 | G31: =SUM(F31,E31,C31-D31) -> -3
A32: 46053 | B32: Taival | C32: 1 | D32: 2 | E32: 0 | F32: 0 | G32: =SUM(F32,E32,C32-D32) -> -1
A33: 46054 | B33: Taival | C33: 1 | D33: 1 | E33: 0 | F33: 0 | G33: =SUM(F33,E33,C33-D33) -> 0
A34: 46055 | B34: Taival | C34: 0 | D34: 2 | E34: 0 | F34: 0 | G34: =SUM(F34,E34,C34-D34) -> -2 | H34: =SUM(G34:G40) -> -6
A35: 46056 | B35: Taival | C35: 2 | D35: 0 | E35: 0 | F35: 0 | G35: =SUM(F35,E35,C35-D35) -> 2
A36: 46057 | B36: Taival | C36: 0 | D36: 1 | E36: 0 | F36: 0 | G36: =SUM(F36,E36,C36-D36) -> -1
A37: 46058 | B37: Taival | C37: 1 | D37: 1 | E37: 0 | F37: 0 | G37: =SUM(F37,E37,C37-D37) -> 0
A38: 46059 | B38: Taival | C38: 2 | D38: 2 | E38: 0 | F38: 0 | G38: =SUM(F38,E38,C38-D38) -> 0
A39: 46060 | B39: Taival | C39: 0 | D39: 2 | E39: 0 | F39: 0 | G39: =SUM(F39,E39,C39-D39) -> -2
A40: 46061 | B40: Taival | C40: 1 | D40: 4 | E40: 0 | F40: 0 | G40: =SUM(F40,E40,C40-D40) -> -3
...

Sheet Colossus - Eternal Blight_WL
A1: DateLocal | B1: Game | C1: Adds | D1: Deletes | E1: Purchases And Activations | F1: Gifts | G1: Net Wishlist | H1: Weekly Net | I1: Monthly Net
A2: 46023 | B2: Colossus - Eternal Blight | C2: 6 | D2: 2 | E2: 0 | F2: 0 | G2: =SUM(F2,E2,C2-D2) -> 4 | H2: =SUM(G2:G5) -> 22
A3: 46024 | B3: Colossus - Eternal Blight | C3: 8 | D3: 1 | E3: 0 | F3: 0 | G3: =SUM(F3,E3,C3-D3) -> 7
A4: 46025 | B4: Colossus - Eternal Blight | C4: 5 | D4: 2 | E4: 0 | F4: 0 | G4: =SUM(F4,E4,C4-D4) -> 3
A5: 46026 | B5: Colossus - Eternal Blight | C5: 8 | D5: 0 | E5: 0 | F5: 0 | G5: =SUM(F5,E5,C5-D5) -> 8
A6: 46027 | B6: Colossus - Eternal Blight | C6: 7 | D6: 3 | E6: 0 | F6: 0 | G6: =SUM(F6,E6,C6-D6) -> 4 | H6: =SUM(G6:G12) -> 22
A7: 46028 | B7: Colossus - Eternal Blight | C7: 3 | D7: 0 | E7: 0 | F7: 0 | G7: =SUM(F7,E7,C7-D7) -> 3
A8: 46029 | B8: Colossus - Eternal Blight | C8: 2 | D8: 0 | E8: 0 | F8: 0 | G8: =SUM(F8,E8,C8-D8) -> 2 | K8: Data CSV. To be added here
A9: 46030 | B9: Colossus - Eternal Blight | C9: 3 | D9: 0 | E9: 0 | F9: 0 | G9: =SUM(F9,E9,C9-D9) -> 3
A10: 46031 | B10: Colossus - Eternal Blight | C10: 3 | D10: 1 | E10: 0 | F10: 0 | G10: =SUM(F10,E10,C10-D10) -> 2
A11: 46032 | B11: Colossus - Eternal Blight | C11: 5 | D11: 0 | E11: 0 | F11: 0 | G11: =SUM(F11,E11,C11-D11) -> 5
A12: 46033 | B12: Colossus - Eternal Blight | C12: 4 | D12: 1 | E12: 0 | F12: 0 | G12: =SUM(F12,E12,C12-D12) -> 3
A13: 46034 | B13: Colossus - Eternal Blight | C13: 6 | D13: 0 | E13: 0 | F13: 0 | G13: =SUM(F13,E13,C13-D13) -> 6 | H13: =SUM(G13:G19) -> 23
A14: 46035 | B14: Colossus - Eternal Blight | C14: 3 | D14: 2 | E14: 0 | F14: 0 | G14: =SUM(F14,E14,C14-D14) -> 1
A15: 46036 | B15: Colossus - Eternal Blight | C15: 4 | D15: 0 | E15: 0 | F15: 0 | G15: =SUM(F15,E15,C15-D15) -> 4
A16: 46037 | B16: Colossus - Eternal Blight | C16: 5 | D16: 1 | E16: 0 | F16: 0 | G16: =SUM(F16,E16,C16-D16) -> 4
A17: 46038 | B17: Colossus - Eternal Blight | C17: 4 | D17: 1 | E17: 0 | F17: 0 | G17: =SUM(F17,E17,C17-D17) -> 3
A18: 46039 | B18: Colossus - Eternal Blight | C18: 5 | D18: 1 | E18: 0 | F18: 0 | G18: =SUM(F18,E18,C18-D18) -> 4
A19: 46040 | B19: Colossus - Eternal Blight | C19: 1 | D19: 0 | E19: 0 | F19: 0 | G19: =SUM(F19,E19,C19-D19) -> 1
A20: 46041 | B20: Colossus - Eternal Blight | C20: 0 | D20: 1 | E20: 0 | F20: 0 | G20: =SUM(F20,E20,C20-D20) -> -1 | H20: =SUM(G20:G26) -> 20
A21: 46042 | B21: Colossus - Eternal Blight | C21: 5 | D21: 1 | E21: 0 | F21: 0 | G21: =SUM(F21,E21,C21-D21) -> 4
A22: 46043 | B22: Colossus - Eternal Blight | C22: 4 | D22: 0 | E22: 0 | F22: 0 | G22: =SUM(F22,E22,C22-D22) -> 4
A23: 46044 | B23: Colossus - Eternal Blight | C23: 7 | D23: 2 | E23: 0 | F23: 0 | G23: =SUM(F23,E23,C23-D23) -> 5
A24: 46045 | B24: Colossus - Eternal Blight | C24: 2 | D24: 1 | E24: 0 | F24: 0 | G24: =SUM(F24,E24,C24-D24) -> 1
A25: 46046 | B25: Colossus - Eternal Blight | C25: 4 | D25: 0 | E25: 0 | F25: 0 | G25: =SUM(F25,E25,C25-D25) -> 4
A26: 46047 | B26: Colossus - Eternal Blight | C26: 4 | D26: 1 | E26: 0 | F26: 0 | G26: =SUM(F26,E26,C26-D26) -> 3
A27: 46048 | B27: Colossus - Eternal Blight | C27: 3 | D27: 1 | E27: 0 | F27: 0 | G27: =SUM(F27,E27,C27-D27) -> 2 | H27: =SUM(G27:G33) -> 286
A28: 46049 | B28: Colossus - Eternal Blight | C28: 2 | D28: 1 | E28: 1 | F28: 0 | G28: =SUM(F28,E28,C28-D28) -> 2
A29: 46050 | B29: Colossus - Eternal Blight | C29: 119 | D29: 4 | E29: 0 | F29: 0 | G29: =SUM(F29,E29,C29-D29) -> 115
A30: 46051 | B30: Colossus - Eternal Blight | C30: 101 | D30: 2 | E30: 0 | F30: 0 | G30: =SUM(F30,E30,C30-D30) -> 99
A31: 46052 | B31: Colossus - Eternal Blight | C31: 27 | D31: 0 | E31: 0 | F31: 0 | G31: =SUM(F31,E31,C31-D31) -> 27
A32: 46053 | B32: Colossus - Eternal Blight | C32: 25 | D32: 1 | E32: 0 | F32: 0 | G32: =SUM(F32,E32,C32-D32) -> 24
A33: 46054 | B33: Colossus - Eternal Blight | C33: 18 | D33: 1 | E33: 0 | F33: 0 | G33: =SUM(F33,E33,C33-D33) -> 17
A34: 46055 | B34: Colossus - Eternal Blight | C34: 29 | D34: 0 | E34: 0 | F34: 0 | G34: =SUM(F34,E34,C34-D34) -> 29 | H34: =SUM(G34:G40) -> 90
A35: 46056 | B35: Colossus - Eternal Blight | C35: 16 | D35: 1 | E35: 0 | F35: 0 | G35: =SUM(F35,E35,C35-D35) -> 15
A36: 46057 | B36: Colossus - Eternal Blight | C36: 13 | D36: 0 | E36: 0 | F36: 0 | G36: =SUM(F36,E36,C36-D36) -> 13
A37: 46058 | B37: Colossus - Eternal Blight | C37: 12 | D37: 0 | E37: 0 | F37: 0 | G37: =SUM(F37,E37,C37-D37) -> 12
A38: 46059 | B38: Colossus - Eternal Blight | C38: 5 | D38: 3 | E38: 0 | F38: 0 | G38: =SUM(F38,E38,C38-D38) -> 2
A39: 46060 | B39: Colossus - Eternal Blight | C39: 9 | D39: 2 | E39: 0 | F39: 0 | G39: =SUM(F39,E39,C39-D39) -> 7
A40: 46061 | B40: Colossus - Eternal Blight | C40: 13 | D40: 1 | E40: 0 | F40: 0 | G40: =SUM(F40,E40,C40-D40) -> 12
...

Sheet Petunia's Purgatory_WL
A1: DateLocal | B1: Game | C1: Adds | D1: Deletes | E1: Purchases And Activations | F1: Gifts | G1: Net Wishlist | H1: Weekly Net | I1: Monthly Net
A2: 46023 | B2: Petunia's Purgatory | C2: 40 | D2: 2 | E2: 0 | F2: 0 | G2: =SUM(C2,E2,F2-D2) -> 38 | H2: =SUM(G2:G5) -> 155
A3: 46024 | B3: Petunia's Purgatory | C3: 78 | D3: 4 | E3: 0 | F3: 0 | G3: =SUM(C3,E3,F3-D3) -> 74
A4: 46025 | B4: Petunia's Purgatory | C4: 29 | D4: 2 | E4: 0 | F4: 0 | G4: =SUM(C4,E4,F4-D4) -> 27
A5: 46026 | B5: Petunia's Purgatory | C5: 16 | D5: 0 | E5: 0 | F5: 0 | G5: =SUM(C5,E5,F5-D5) -> 16
A6: 46027 | B6: Petunia's Purgatory | C6: 10 | D6: 1 | E6: 0 | F6: 0 | G6: =SUM(C6,E6,F6-D6) -> 9 | H6: =SUM(G6:G12) -> 36
A7: 46028 | B7: Petunia's Purgatory | C7: 8 | D7: 3 | E7: 0 | F7: 0 | G7: =SUM(C7,E7,F7-D7) -> 5
A8: 46029 | B8: Petunia's Purgatory | C8: 7 | D8: 0 | E8: 0 | F8: 0 | G8: =SUM(C8,E8,F8-D8) -> 7
A9: 46030 | B9: Petunia's Purgatory | C9: 4 | D9: 0 | E9: 0 | F9: 0 | G9: =SUM(C9,E9,F9-D9) -> 4
A10: 46031 | B10: Petunia's Purgatory | C10: 4 | D10: 0 | E10: 0 | F10: 0 | G10: =SUM(C10,E10,F10-D10) -> 4 | K10: Data CSV. To be added here
A11: 46032 | B11: Petunia's Purgatory | C11: 5 | D11: 0 | E11: 0 | F11: 0 | G11: =SUM(C11,E11,F11-D11) -> 5
A12: 46033 | B12: Petunia's Purgatory | C12: 2 | D12: 0 | E12: 0 | F12: 0 | G12: =SUM(C12,E12,F12-D12) -> 2
A13: 46034 | B13: Petunia's Purgatory | C13: 5 | D13: 1 | E13: 0 | F13: 0 | G13: =SUM(C13,E13,F13-D13) -> 4 | H13: =SUM(G13:G19) -> 16
A14: 46035 | B14: Petunia's Purgatory | C14: 4 | D14: 1 | E14: 0 | F14: 0 | G14: =SUM(C14,E14,F14-D14) -> 3
A15: 46036 | B15: Petunia's Purgatory | C15: 1 | D15: 0 | E15: 0 | F15: 0 | G15: =SUM(C15,E15,F15-D15) -> 1
A16: 46037 | B16: Petunia's Purgatory | C16: 3 | D16: 1 | E16: 0 | F16: 0 | G16: =SUM(C16,E16,F16-D16) -> 2
A17: 46038 | B17: Petunia's Purgatory | C17: 4 | D17: 1 | E17: 0 | F17: 0 | G17: =SUM(C17,E17,F17-D17) -> 3
A18: 46039 | B18: Petunia's Purgatory | C18: 1 | D18: 0 | E18: 0 | F18: 0 | G18: =SUM(C18,E18,F18-D18) -> 1
A19: 46040 | B19: Petunia's Purgatory | C19: 2 | D19: 0 | E19: 0 | F19: 0 | G19: =SUM(C19,E19,F19-D19) -> 2
A20: 46041 | B20: Petunia's Purgatory | C20: 2 | D20: 0 | E20: 0 | F20: 0 | G20: =SUM(C20,E20,F20-D20) -> 2 | H20: =SUM(G20:G26) -> 12
A21: 46042 | B21: Petunia's Purgatory | C21: 1 | D21: 0 | E21: 0 | F21: 0 | G21: =SUM(C21,E21,F21-D21) -> 1
A22: 46043 | B22: Petunia's Purgatory | C22: 6 | D22: 1 | E22: 0 | F22: 0 | G22: =SUM(C22,E22,F22-D22) -> 5
A23: 46044 | B23: Petunia's Purgatory | C23: 1 | D23: 1 | E23: 0 | F23: 0 | G23: =SUM(C23,E23,F23-D23) -> 0
A24: 46045 | B24: Petunia's Purgatory | C24: 3 | D24: 0 | E24: 0 | F24: 0 | G24: =SUM(C24,E24,F24-D24) -> 3
A25: 46046 | B25: Petunia's Purgatory | C25: 3 | D25: 1 | E25: 0 | F25: 0 | G25: =SUM(C25,E25,F25-D25) -> 2
A26: 46047 | B26: Petunia's Purgatory | C26: 0 | D26: 1 | E26: 0 | F26: 0 | G26: =SUM(C26,E26,F26-D26) -> -1
A27: 46048 | B27: Petunia's Purgatory | C27: 7 | D27: 1 | E27: 0 | F27: 0 | G27: =SUM(C27,E27,F27-D27) -> 6 | H27: =SUM(G27:G33) -> 23
A28: 46049 | B28: Petunia's Purgatory | C28: 0 | D28: 1 | E28: 0 | F28: 0 | G28: =SUM(C28,E28,F28-D28) -> -1
A29: 46050 | B29: Petunia's Purgatory | C29: 7 | D29: 0 | E29: 0 | F29: 0 | G29: =SUM(C29,E29,F29-D29) -> 7
A30: 46051 | B30: Petunia's Purgatory | C30: 4 | D30: 0 | E30: 0 | F30: 0 | G30: =SUM(C30,E30,F30-D30) -> 4
A31: 46052 | B31: Petunia's Purgatory | C31: 5 | D31: 0 | E31: 0 | F31: 0 | G31: =SUM(C31,E31,F31-D31) -> 5
A32: 46053 | B32: Petunia's Purgatory | C32: 2 | D32: 1 | E32: 0 | F32: 0 | G32: =SUM(C32,E32,F32-D32) -> 1
A33: 46054 | B33: Petunia's Purgatory | C33: 2 | D33: 2 | E33: 1 | F33: 0 | G33: =SUM(C33,E33,F33-D33) -> 1
A34: 46055 | B34: Petunia's Purgatory | C34: 8 | D34: 0 | E34: 0 | F34: 0 | G34: =SUM(C34,E34,F34-D34) -> 8 | H34: =SUM(G34:G40) -> 30
